Workbook

Sheet INSTRUÇÕES
B2: PLANILHA DE CONTROLE · IMAGENS AMAZON · NEW PET
B3: Acompanha o "Guia de Imagens Amazon – New Pet". Produtos e EANs puxados do cadastro da New Pet na Amazon em 10/10/2026.
B5: Como usar
B6: 1. Coloque esta planilha | C6: Dentro da pasta "NEWPET - IMAGENS AMAZON" no Google Drive (Arquivo → Importar ou arrastar o arquivo e abrir com Google Planilhas). A mesma pasta onde ficam as imagens, sem subpastas.
B7: 2. Aba PRODUTOS | C7: Uma linha por produto à venda. Escolha o Modelo de A+ (A ou B) e confira a coluna "A+ igual ao EAN" (já sugerida: tamanhos do mesmo produto usam o A+ do maior tamanho).
B8: 3. Aba ARQUIVOS | C8: A lista exata de arquivos que cada produto precisa, com o nome pronto. Copie o nome da coluna "Nome exato do arquivo" ao salvar a imagem e marque o Status como "Na pasta" quando ela estiver no Drive.
B9: 4. Aba MODELOS | C9: O que mostrar em cada posição e o tamanho de cada imagem, para a ração e para petiscos e higiene. Consulta apenas.
B10: 5. Avise a START | C10: Quando a coluna "Completo?" da aba PRODUTOS estiver "SIM" para os produtos do lote. "Completo" considera as imagens obrigatórias; as recomendadas aparecem em coluna própria e devem ser enviadas sempre que possível.
B12: Cores
B13: Amarelo | C13: Preencher ou escolher (Modelo de A+, A+ igual ao EAN, Status, Observações).
B14: Cinza | C14: Dados do cadastro e fórmulas. Não alterar: são eles que garantem que a imagem vai para o produto certo.
B16: Regras dos nomes de arquivo
B17: Formato | C17: EAN.CÓDIGO.jpg → exemplo: 7898968541504.MAIN.jpg (separado por ponto, código em maiúsculas, sem espaços).
B18: Não renomear | C18: Use exatamente o nome da aba ARQUIVOS. Não acrescente sabor, peso, "final", "(1)" ou "cópia".
B19: Formato da imagem | C19: Galeria: JPG 2000 × 2000 px, RGB. A+: JPG ou PNG no tamanho exato indicado.
B20: Extras e vídeo | C20: Opcionais: EAN.EXTRA1.jpg, EAN.EXTRA2.jpg e EAN.VIDEO.mp4 podem ir para a pasta sem constar nesta planilha.
B21: Textos | C21: Não é preciso enviar textos. Título, bullets, descrição e textos do A+ são criados pela START. De vocês, só o texto desenhado dentro das imagens.
B23: Atenção
B24: Palito 8" Rígido 10 un. | C24: Cadastrado na Amazon com código de 14 dígitos (17908591301158). Usar esse código no nome dos arquivos, exatamente como está na aba ARQUIVOS.
B25: Produto faltando? | C25: Se algum produto à venda não aparece aqui, ou um EAN não corresponde à embalagem, avise a START antes de produzir as imagens.

Sheet PRODUTOS
A1: PRODUTOS · New Pet · uma linha por produto à venda (cadastro Amazon em 10/10/2026)
A2: Amarelo = preencher/escolher · Cinza = cadastro e fórmulas, não alterar. "A+ igual ao EAN" já vem sugerido (tamanhos menores usam o A+ do maior); apague para o produto ter A+ próprio.
A3: Nº | B3: EAN | C3: SKU | D3: ASIN | E3: Produto (cadastro Amazon) | F3: Tipo | G3: Família (mesmo produto, outros tamanhos) | H3: Peso / tamanho | I3: Modelo de A+ | J3: A+ igual ao EAN | K3: Obrigatórias (total) | L3: Obrigatórias na pasta | M3: Recomendadas na pasta | N3: Completo? | O3: Observações
A4: 1 | B4: 7898968541504 | C4: 7898968541504 | D4: B0H7LGC65H | E4: New Dots Ração Seca Premium para Cães Adultos - 15 kg | F4: Ração | G4: New Dots Ração Seca Premium para Cães Adultos | H4: 15 kg | I4: A | K4: =COUNTIFS(ARQUIVOS!$A:$A,$B4,ARQUIVOS!$J:$J,"SIM") -> 14 | L4: =COUNTIFS(ARQUIVOS!$A:$A,$B4,ARQUIVOS!$J:$J,"SIM",ARQUIVOS!$K:$K,"Na pasta") -> 0 | M4: =COUNTIFS(ARQUIVOS!$A:$A,$B4,ARQUIVOS!$J:$J,"RECOMENDADA",ARQUIVOS!$K:$K,"Na pasta")&" de "&COUNTIFS(ARQUIVOS!$A:$A,$B4,ARQUIVOS!$J:$J,"RECOMENDADA") -> 0 de 3 | N4: =IF(L4>=K4,"SIM","NÃO") -> NÃO
A5: 2 | B5: 7908591301144 | C5: 7908591301144 | D5: B0H7L955P6 | E5: New Dots Ração Seca Premium para Cães Adultos - 10,1 kg | F5: Ração | G5: New Dots Ração Seca Premium para Cães Adultos | H5: 10,1 kg | I5: A | J5: 7898968541504 | K5: =COUNTIFS(ARQUIVOS!$A:$A,$B5,ARQUIVOS!$J:$J,"SIM") -> 7 | L5: =COUNTIFS(ARQUIVOS!$A:$A,$B5,ARQUIVOS!$J:$J,"SIM",ARQUIVOS!$K:$K,"Na pasta") -> 0 | M5: =COUNTIFS(ARQUIVOS!$A:$A,$B5,ARQUIVOS!$J:$J,"RECOMENDADA",ARQUIVOS!$K:$K,"Na pasta")&" de "&COUNTIFS(ARQUIVOS!$A:$A,$B5,ARQUIVOS!$J:$J,"RECOMENDADA") -> 0 de 3 | N5: =IF(L5>=K5,"SIM","NÃO") -> NÃO
A6: 3 | B6: 7898968541467 | C6: 7898968541467 | D6: B0H7KXDGD7 | E6: New Dots Ração Seca Premium para Cães Adultos - 5 kg | F6: Ração | G6: New Dots Ração Seca Premium para Cães Adultos | H6: 5 kg | I6: A | J6: 7898968541504 | K6: =COUNTIFS(ARQUIVOS!$A:$A,$B6,ARQUIVOS!$J:$J,"SIM") -> 7 | L6: =COUNTIFS(ARQUIVOS!$A:$A,$B6,ARQUIVOS!$J:$J,"SIM",ARQUIVOS!$K:$K,"Na pasta") -> 0 | M6: =COUNTIFS(ARQUIVOS!$A:$A,$B6,ARQUIVOS!$J:$J,"RECOMENDADA",ARQUIVOS!$K:$K,"Na pasta")&" de "&COUNTIFS(ARQUIVOS!$A:$A,$B6,ARQUIVOS!$J:$J,"RECOMENDADA") -> 0 de 3 | N6: =IF(L6>=K6,"SIM","NÃO") -> NÃO
A7: 4 | B7: 7898968541450 | C7: 7898968541450 | D7: B0H7KWY5KT | E7: New Dots Ração Seca Premium para Cães Adultos - 1 kg | F7: Ração | G7: New Dots Ração Seca Premium para Cães Adultos | H7: 1 kg | I7: A | J7: 7898968541504 | K7: =COUNTIFS(ARQUIVOS!$A:$A,$B7,ARQUIVOS!$J:$J,"SIM") -> 7 | L7: =COUNTIFS(ARQUIVOS!$A:$A,$B7,ARQUIVOS!$J:$J,"SIM",ARQUIVOS!$K:$K,"Na pasta") -> 0 | M7: =COUNTIFS(ARQUIVOS!$A:$A,$B7,ARQUIVOS!$J:$J,"RECOMENDADA",ARQUIVOS!$K:$K,"Na pasta")&" de "&COUNTIFS(ARQUIVOS!$A:$A,$B7,ARQUIVOS!$J:$J,"RECOMENDADA") -> 0 de 3 | N7: =IF(L7>=K7,"SIM","NÃO") -> NÃO
A8: 5 | B8: 7898968541535 | C8: 7898968541535 | D8: B0H7LGV2SK | E8: New Dots Ração Seca Premium para Cães Adultos de Raças Pequenas - 20 kg | F8: Ração | G8: New Dots Ração Seca Premium para Cães Adultos de Raças Pequenas | H8: 20 kg | I8: A | K8: =COUNTIFS(ARQUIVOS!$A:$A,$B8,ARQUIVOS!$J:$J,"SIM") -> 14 | L8: =COUNTIFS(ARQUIVOS!$A:$A,$B8,ARQUIVOS!$J:$J,"SIM",ARQUIVOS!$K:$K,"Na pasta") -> 0 | M8: =COUNTIFS(ARQUIVOS!$A:$A,$B8,ARQUIVOS!$J:$J,"RECOMENDADA",ARQUIVOS!$K:$K,"Na pasta")&" de "&COUNTIFS(ARQUIVOS!$A:$A,$B8,ARQUIVOS!$J:$J,"RECOMENDADA") -> 0 de 3 | N8: =IF(L8>=K8,"SIM","NÃO") -> NÃO
A9: 6 | B9: 7898968541528 | C9: 7898968541528 | D9: B0H7KZH2XV | E9: New Dots Ração Seca Premium para Cães Adultos de Raças Pequenas - 5 kg | F9: Ração | G9: New Dots Ração Seca Premium para Cães Adultos de Raças Pequenas | H9: 5 kg | I9: A | J9: 7898968541535 | K9: =COUNTIFS(ARQUIVOS!$A:$A,$B9,ARQUIVOS!$J:$J,"SIM") -> 7 | L9: =COUNTIFS(ARQUIVOS!$A:$A,$B9,ARQUIVOS!$J:$J,"SIM",ARQUIVOS!$K:$K,"Na pasta") -> 0 | M9: =COUNTIFS(ARQUIVOS!$A:$A,$B9,ARQUIVOS!$J:$J,"RECOMENDADA",ARQUIVOS!$K:$K,"Na pasta")&" de "&COUNTIFS(ARQUIVOS!$A:$A,$B9,ARQUIVOS!$J:$J,"RECOMENDADA") -> 0 de 3 | N9: =IF(L9>=K9,"SIM","NÃO") -> NÃO
A10: 7 | B10: 7898968541511 | C10: 7898968541511 | D10: B0H7KZFSLZ | E10: New Dots Ração Seca Premium para Cães Adultos de Raças Pequenas - 1 kg | F10: Ração | G10: New Dots Ração Seca Premium para Cães Adultos de Raças Pequenas | H10: 1 kg | I10: A | J10: 7898968541535 | K10: =COUNTIFS(ARQUIVOS!$A:$A,$B10,ARQUIVOS!$J:$J,"SIM") -> 7 | L10: =COUNTIFS(ARQUIVOS!$A:$A,$B10,ARQUIVOS!$J:$J,"SIM",ARQUIVOS!$K:$K,"Na pasta") -> 0 | M10: =COUNTIFS(ARQUIVOS!$A:$A,$B10,ARQUIVOS!$J:$J,"RECOMENDADA",ARQUIVOS!$K:$K,"Na pasta")&" de "&COUNTIFS(ARQUIVOS!$A:$A,$B10,ARQUIVOS!$J:$J,"RECOMENDADA") -> 0 de 3 | N10: =IF(L10>=K10,"SIM","NÃO") -> NÃO
A11: 8 | B11: 7898968541566 | C11: 7898968541566 | D11: B0H7L1QMMZ | E11: New Dots Ração Seca Premium para Cães Filhotes - 20 kg | F11: Ração | G11: New Dots Ração Seca Premium para Cães Filhotes | H11: 20 kg | I11: A | K11: =COUNTIFS(ARQUIVOS!$A:$A,$B11,ARQUIVOS!$J:$J,"SIM") -> 14 | L11: =COUNTIFS(ARQUIVOS!$A:$A,$B11,ARQUIVOS!$J:$J,"SIM",ARQUIVOS!$K:$K,"Na pasta") -> 0 | M11: =COUNTIFS(ARQUIVOS!$A:$A,$B11,ARQUIVOS!$J:$J,"RECOMENDADA",ARQUIVOS!$K:$K,"Na pasta")&" de "&COUNTIFS(ARQUIVOS!$A:$A,$B11,ARQUIVOS!$J:$J,"RECOMENDADA") -> 0 de 3 | N11: =IF(L11>=K11,"SIM","NÃO") -> NÃO
A12: 9 | B12: 7898968541559 | C12: 7898968541559 | D12: B0H7LG9LK2 | E12: New Dots Ração Seca Premium para Cães Filhotes - 5 kg | F12: Ração | G12: New Dots Ração Seca Premium para Cães Filhotes | H12: 5 kg | I12: A | J12: 7898968541566 | K12: =COUNTIFS(ARQUIVOS!$A:$A,$B12,ARQUIVOS!$J:$J,"SIM") -> 7 | L12: =COUNTIFS(ARQUIVOS!$A:$A,$B12,ARQUIVOS!$J:$J,"SIM",ARQUIVOS!$K:$K,"Na pasta") -> 0 | M12: =COUNTIFS(ARQUIVOS!$A:$A,$B12,ARQUIVOS!$J:$J,"RECOMENDADA",ARQUIVOS!$K:$K,"Na pasta")&" de "&COUNTIFS(ARQUIVOS!$A:$A,$B12,ARQUIVOS!$J:$J,"RECOMENDADA") -> 0 de 3 | N12: =IF(L12>=K12,"SIM","NÃO") -> NÃO
A13: 10 | B13: 7898968541542 | C13: 7898968541542 | D13: B0H7L3BHLH | E13: New Dots Ração Seca Premium para Cães Filhotes - 1 kg | F13: Ração | G13: New Dots Ração Seca Premium para Cães Filhotes | H13: 1 kg | I13: A | J13: 7898968541566 | K13: =COUNTIFS(ARQUIVOS!$A:$A,$B13,ARQUIVOS!$J:$J,"SIM") -> 7 | L13: =COUNTIFS(ARQUIVOS!$A:$A,$B13,ARQUIVOS!$J:$J,"SIM",ARQUIVOS!$K:$K,"Na pasta") -> 0 | M13: =COUNTIFS(ARQUIVOS!$A:$A,$B13,ARQUIVOS!$J:$J,"RECOMENDADA",ARQUIVOS!$K:$K,"Na pasta")&" de "&COUNTIFS(ARQUIVOS!$A:$A,$B13,ARQUIVOS!$J:$J,"RECOMENDADA") -> 0 de 3 | N13: =IF(L13>=K13,"SIM","NÃO") -> NÃO
A14: 11 | B14: 7898968541597 | C14: 7898968541597 | D14: B0H7LG5GWZ | E14: New Dots Ração Seca Premium para Gatos Adultos - 20 kg | F14: Ração | G14: New Dots Ração Seca Premium para Gatos Adultos | H14: 20 kg | I14: A | K14: =COUNTIFS(ARQUIVOS!$A:$A,$B14,ARQUIVOS!$J:$J,"SIM") -> 14 | L14: =COUNTIFS(ARQUIVOS!$A:$A,$B14,ARQUIVOS!$J:$J,"SIM",ARQUIVOS!$K:$K,"Na pasta") -> 0 | M14: =COUNTIFS(ARQUIVOS!$A:$A,$B14,ARQUIVOS!$J:$J,"RECOMENDADA",ARQUIVOS!$K:$K,"Na pasta")&" de "&COUNTIFS(ARQUIVOS!$A:$A,$B14,ARQUIVOS!$J:$J,"RECOMENDADA") -> 0 de 3 | N14: =IF(L14>=K14,"SIM","NÃO") -> NÃO
A15: 12 | B15: 7898968541573 | C15: 7898968541573 | D15: B0H7LD2TGC | E15: New Dots Ração Seca Premium para Gatos Adultos - 1 kg | F15: Ração | G15: New Dots Ração Seca Premium para Gatos Adultos | H15: 1 kg | I15: A | J15: 7898968541597 | K15: =COUNTIFS(ARQUIVOS!$A:$A,$B15,ARQUIVOS!$J:$J,"SIM") -> 7 | L15: =COUNTIFS(ARQUIVOS!$A:$A,$B15,ARQUIVOS!$J:$J,"SIM",ARQUIVOS!$K:$K,"Na pasta") -> 0 | M15: =COUNTIFS(ARQUIVOS!$A:$A,$B15,ARQUIVOS!$J:$J,"RECOMENDADA",ARQUIVOS!$K:$K,"Na pasta")&" de "&COUNTIFS(ARQUIVOS!$A:$A,$B15,ARQUIVOS!$J:$J,"RECOMENDADA") -> 0 de 3 | N15: =IF(L15>=K15,"SIM","NÃO") -> NÃO
A16: 13 | B16: 7908591300666 | C16: 7908591300666 | D16: B0H7KWW8M4 | E16: New Dots Ração Seca Premium para Gatos Adultos Castrados - 20 kg | F16: Ração | G16: New Dots Ração Seca Premium para Gatos Adultos Castrados | H16: 20 kg | I16: A | K16: =COUNTIFS(ARQUIVOS!$A:$A,$B16,ARQUIVOS!$J:$J,"SIM") -> 14 | L16: =COUNTIFS(ARQUIVOS!$A:$A,$B16,ARQUIVOS!$J:$J,"SIM",ARQUIVOS!$K:$K,"Na pasta") -> 0 | M16: =COUNTIFS(ARQUIVOS!$A:$A,$B16,ARQUIVOS!$J:$J,"RECOMENDADA",ARQUIVOS!$K:$K,"Na pasta")&" de "&COUNTIFS(ARQUIVOS!$A:$A,$B16,ARQUIVOS!$J:$J,"RECOMENDADA") -> 0 de 3 | N16: =IF(L16>=K16,"SIM","NÃO") -> NÃO
A17: 14 | B17: 7908591300413 | C17: 7908591300413 | D17: B0H7L2N7GF | E17: New Dots Ração Seca Premium para Gatos Adultos Castrados - 11 kg | F17: Ração | G17: New Dots Ração Seca Premium para Gatos Adultos Castrados | H17: 11 kg | I17: A | J17: 7908591300666 | K17: =COUNTIFS(ARQUIVOS!$A:$A,$B17,ARQUIVOS!$J:$J,"SIM") -> 7 | L17: =COUNTIFS(ARQUIVOS!$A:$A,$B17,ARQUIVOS!$J:$J,"SIM",ARQUIVOS!$K:$K,"Na pasta") -> 0 | M17: =COUNTIFS(ARQUIVOS!$A:$A,$B17,ARQUIVOS!$J:$J,"RECOMENDADA",ARQUIVOS!$K:$K,"Na pasta")&" de "&COUNTIFS(ARQUIVOS!$A:$A,$B17,ARQUIVOS!$J:$J,"RECOMENDADA") -> 0 de 3 | N17: =IF(L17>=K17,"SIM","NÃO") -> NÃO
A18: 15 | B18: 7908591300406 | C18: 7908591300406 | D18: B0H7KWTZ9P | E18: New Dots Ração Seca Premium para Gatos Adultos Castrados - 1 kg | F18: Ração | G18: New Dots Ração Seca Premium para Gatos Adultos Castrados | H18: 1 kg | I18: A | J18: 7908591300666 | K18: =COUNTIFS(ARQUIVOS!$A:$A,$B18,ARQUIVOS!$J:$J,"SIM") -> 7 | L18: =COUNTIFS(ARQUIVOS!$A:$A,$B18,ARQUIVOS!$J:$J,"SIM",ARQUIVOS!$K:$K,"Na pasta") -> 0 | M18: =COUNTIFS(ARQUIVOS!$A:$A,$B18,ARQUIVOS!$J:$J,"RECOMENDADA",ARQUIVOS!$K:$K,"Na pasta")&" de "&COUNTIFS(ARQUIVOS!$A:$A,$B18,ARQUIVOS!$J:$J,"RECOMENDADA") -> 0 de 3 | N18: =IF(L18>=K18,"SIM","NÃO") -> NÃO
A19: 16 | B19: 7898968541283 | C19: 1001 | D19: B0FH32BP56 | E19: Ração Seca Natural Dots para Cães Adultos - Pacote 15 kg | F19: Ração | G19: Ração Seca Natural Dots para Cães Adultos | H19: 15 kg | I19: A | K19: =COUNTIFS(ARQUIVOS!$A:$A,$B19,ARQUIVOS!$J:$J,"SIM") -> 14 | L19: =COUNTIFS(ARQUIVOS!$A:$A,$B19,ARQUIVOS!$J:$J,"SIM",ARQUIVOS!$K:$K,"Na pasta") -> 0 | M19: =COUNTIFS(ARQUIVOS!$A:$A,$B19,ARQUIVOS!$J:$J,"RECOMENDADA",ARQUIVOS!$K:$K,"Na pasta")&" de "&COUNTIFS(ARQUIVOS!$A:$A,$B19,ARQUIVOS!$J:$J,"RECOMENDADA") -> 0 de 3 | N19: =IF(L19>=K19,"SIM","NÃO") -> NÃO
A20: 17 | B20: 7898968541269 | C20: 1195 | D20: B0FH347L7H | E20: Ração Seca Natural Dots para Cães Adultos - Pacote 1 kg | F20: Ração | G20: Ração Seca Natural Dots para Cães Adultos | H20: 1 kg | I20: A | J20: 7898968541283 | K20: =COUNTIFS(ARQUIVOS!$A:$A,$B20,ARQUIVOS!$J:$J,"SIM") -> 7 | L20: =COUNTIFS(ARQUIVOS!$A:$A,$B20,ARQUIVOS!$J:$J,"SIM",ARQUIVOS!$K:$K,"Na pasta") -> 0 | M20: =COUNTIFS(ARQUIVOS!$A:$A,$B20,ARQUIVOS!$J:$J,"RECOMENDADA",ARQUIVOS!$K:$K,"Na pasta")&" de "&COUNTIFS(ARQUIVOS!$A:$A,$B20,ARQUIVOS!$J:$J,"RECOMENDADA") -> 0 de 3 | N20: =IF(L20>=K20,"SIM","NÃO") -> NÃO
A21: 18 | B21: 7898968541313 | C21: 1075 | D21: B0FH34VLTD | E21: Ração Seca Natural Dots para Cães Filhotes - Pacote 15 kg | F21: Ração | G21: Ração Seca Natural Dots para Cães Filhotes | H21: 15 kg | I21: A | K21: =COUNTIFS(ARQUIVOS!$A:$A,$B21,ARQUIVOS!$J:$J,"SIM") -> 14 | L21: =COUNTIFS(ARQUIVOS!$A:$A,$B21,ARQUIVOS!$J:$J,"SIM",ARQUIVOS!$K:$K,"Na pasta") -> 0 | M21: =COUNTIFS(ARQUIVOS!$A:$A,$B21,ARQUIVOS!$J:$J,"RECOMENDADA",ARQUIVOS!$K:$K,"Na pasta")&" de "&COUNTIFS(ARQUIVOS!$A:$A,$B21,ARQUIVOS!$J:$J,"RECOMENDADA") -> 0 de 3 | N21: =IF(L21>=K21,"SIM","NÃO") -> NÃO
A22: 19 | B22: 7898968541290 | C22: 1070 | D22: B0FH2ZVVMK | E22: Ração Seca Natural Dots para Cães Filhotes - Pacote 1 kg | F22: Ração | G22: Ração Seca Natural Dots para Cães Filhotes | H22: 1 kg | I22: A | J22: 7898968541313 | K22: =COUNTIFS(ARQUIVOS!$A:$A,$B22,ARQUIVOS!$J:$J,"SIM") -> 7 | L22: =COUNTIFS(ARQUIVOS!$A:$A,$B22,ARQUIVOS!$J:$J,"SIM",ARQUIVOS!$K:$K,"Na pasta") -> 0 | M22: =COUNTIFS(ARQUIVOS!$A:$A,$B22,ARQUIVOS!$J:$J,"RECOMENDADA",ARQUIVOS!$K:$K,"Na pasta")&" de "&COUNTIFS(ARQUIVOS!$A:$A,$B22,ARQUIVOS!$J:$J,"RECOMENDADA") -> 0 de 3 | N22: =IF(L22>=K22,"SIM","NÃO") -> NÃO
A23: 20 | B23: 7898968541276 | C23: 1199 | D23: B0FH337MZK | E23: Ração Seca Natural Dots para Cães Sênior - Pacote 15 kg | F23: Ração | G23: Ração Seca Natural Dots para Cães Sênior | H23: 15 kg | I23: A | K23: =COUNTIFS(ARQUIVOS!$A:$A,$B23,ARQUIVOS!$J:$J,"SIM") -> 14 | L23: =COUNTIFS(ARQUIVOS!$A:$A,$B23,ARQUIVOS!$J:$J,"SIM",ARQUIVOS!$K:$K,"Na pasta") -> 0 | M23: =COUNTIFS(ARQUIVOS!$A:$A,$B23,ARQUIVOS!$J:$J,"RECOMENDADA",ARQUIVOS!$K:$K,"Na pasta")&" de "&COUNTIFS(ARQUIVOS!$A:$A,$B23,ARQUIVOS!$J:$J,"RECOMENDADA") -> 0 de 3 | N23: =IF(L23>=K23,"SIM","NÃO") -> NÃO
A24: 21 | B24: 7908591300154 | C24: 1198 | D24: B0FH341T47 | E24: Ração Seca Natural Dots para Cães Sênior - Pacote 1 kg | F24: Ração | G24: Ração Seca Natural Dots para Cães Sênior | H24: 1 kg | I24: A | J24: 7898968541276 | K24: =COUNTIFS(ARQUIVOS!$A:$A,$B24,ARQUIVOS!$J:$J,"SIM") -> 7 | L24: =COUNTIFS(ARQUIVOS!$A:$A,$B24,ARQUIVOS!$J:$J,"SIM",ARQUIVOS!$K:$K,"Na pasta") -> 0 | M24: =COUNTIFS(ARQUIVOS!$A:$A,$B24,ARQUIVOS!$J:$J,"RECOMENDADA",ARQUIVOS!$K:$K,"Na pasta")&" de "&COUNTIFS(ARQUIVOS!$A:$A,$B24,ARQUIVOS!$J:$J,"RECOMENDADA") -> 0 de 3 | N24: =IF(L24>=K24,"SIM","NÃO") -> NÃO
A25: 22 | B25: 7898968541344 | C25: 1196 | D25: B0FH31K58G | E25: Ração Seca Natural Dots para Cães de Raças Pequenas - Pacote 15 kg | F25: Ração | G25: Ração Seca Natural Dots para Cães de Raças Pequenas | H25: 15 kg | I25: A | K25: =COUNTIFS(ARQUIVOS!$A:$A,$B25,ARQUIVOS!$J:$J,"SIM") -> 14 | L25: =COUNTIFS(ARQUIVOS!$A:$A,$B25,ARQUIVOS!$J:$J,"SIM",ARQUIVOS!$K:$K,"Na pasta") -> 0 | M25: =COUNTIFS(ARQUIVOS!$A:$A,$B25,ARQUIVOS!$J:$J,"RECOMENDADA",ARQUIVOS!$K:$K,"Na pasta")&" de "&COUNTIFS(ARQUIVOS!$A:$A,$B25,ARQUIVOS!$J:$J,"RECOMENDADA") -> 0 de 3 | N25: =IF(L25>=K25,"SIM","NÃO") -> NÃO
A26: 23 | B26: 7898968541320 | C26: 1071 | D26: B0FH31X2DG | E26: Ração Seca Natural Dots para Cães de Raças Pequenas - Pacote 1 kg | F26: Ração | G26: Ração Seca Natural Dots para Cães de Raças Pequenas | H26: 1 kg | I26: A | J26: 7898968541344 | K26: =COUNTIFS(ARQUIVOS!$A:$A,$B26,ARQUIVOS!$J:$J,"SIM") -> 7 | L26: =COUNTIFS(ARQUIVOS!$A:$A,$B26,ARQUIVOS!$J:$J,"SIM",ARQUIVOS!$K:$K,"Na pasta") -> 0 | M26: =COUNTIFS(ARQUIVOS!$A:$A,$B26,ARQUIVOS!$J:$J,"RECOMENDADA",ARQUIVOS!$K:$K,"Na pasta")&" de "&COUNTIFS(ARQUIVOS!$A:$A,$B26,ARQUIVOS!$J:$J,"RECOMENDADA") -> 0 de 3 | N26: =IF(L26>=K26,"SIM","NÃO") -> NÃO
A27: 24 | B27: 7898968541382 | C27: 1081 | D27: B0FH34LMJT | E27: Ração Seca Natural Dots para Gatos Adultos - Pacote 11 kg | F27: Ração | G27: Ração Seca Natural Dots para Gatos Adultos | H27: 11 kg | I27: A | K27: =COUNTIFS(ARQUIVOS!$A:$A,$B27,ARQUIVOS!$J:$J,"SIM") -> 14 | L27: =COUNTIFS(ARQUIVOS!$A:$A,$B27,ARQUIVOS!$J:$J,"SIM",ARQUIVOS!$K:$K,"Na pasta") -> 0 | M27: =COUNTIFS(ARQUIVOS!$A:$A,$B27,ARQUIVOS!$J:$J,"RECOMENDADA",ARQUIVOS!$K:$K,"Na pasta")&" de "&COUNTIFS(ARQUIVOS!$A:$A,$B27,ARQUIVOS!$J:$J,"RECOMENDADA") -> 0 de 3 | N27: =IF(L27>=K27,"SIM","NÃO") -> NÃO
A28: 25 | B28: 7898968541368 | C28: 1080 | D28: B0FH33YSNK | E28: Ração Seca Natural Dots para Gatos Adultos - Pacote 1 kg | F28: Ração | G28: Ração Seca Natural Dots para Gatos Adultos | H28: 1 kg | I28: A | J28: 7898968541382 | K28: =COUNTIFS(ARQUIVOS!$A:$A,$B28,ARQUIVOS!$J:$J,"SIM") -> 7 | L28: =COUNTIFS(ARQUIVOS!$A:$A,$B28,ARQUIVOS!$J:$J,"SIM",ARQUIVOS!$K:$K,"Na pasta") -> 0 | M28: =COUNTIFS(ARQUIVOS!$A:$A,$B28,ARQUIVOS!$J:$J,"RECOMENDADA",ARQUIVOS!$K:$K,"Na pasta")&" de "&COUNTIFS(ARQUIVOS!$A:$A,$B28,ARQUIVOS!$J:$J,"RECOMENDADA") -> 0 de 3 | N28: =IF(L28>=K28,"SIM","NÃO") -> NÃO
A29: 26 | B29: 7898968541399 | C29: 1083 | D29: B0FH34NGCJ | E29: Ração Seca Natural Dots para Gatos Castrados - Pacote 11 kg | F29: Ração | G29: Ração Seca Natural Dots para Gatos Castrados | H29: 11 kg | I29: A | K29: =COUNTIFS(ARQUIVOS!$A:$A,$B29,ARQUIVOS!$J:$J,"SIM") -> 14 | L29: =COUNTIFS(ARQUIVOS!$A:$A,$B29,ARQUIVOS!$J:$J,"SIM",ARQUIVOS!$K:$K,"Na pasta") -> 0 | M29: =COUNTIFS(ARQUIVOS!$A:$A,$B29,ARQUIVOS!$J:$J,"RECOMENDADA",ARQUIVOS!$K:$K,"Na pasta")&" de "&COUNTIFS(ARQUIVOS!$A:$A,$B29,ARQUIVOS!$J:$J,"RECOMENDADA") -> 0 de 3 | N29: =IF(L29>=K29,"SIM","NÃO") -> NÃO
A30: 27 | B30: 7898968541375 | C30: 1073 | D30: B0FH32M1DZ | E30: Ração Seca Natural Dots para Gatos Castrados - Pacote 1 kg | F30: Ração | G30: Ração Seca Natural Dots para Gatos Castrados | H30: 1 kg | I30: A | J30: 7898968541399 | K30: =COUNTIFS(ARQUIVOS!$A:$A,$B30,ARQUIVOS!$J:$J,"SIM") -> 7 | L30: =COUNTIFS(ARQUIVOS!$A:$A,$B30,ARQUIVOS!$J:$J,"SIM",ARQUIVOS!$K:$K,"Na pasta") -> 0 | M30: =COUNTIFS(ARQUIVOS!$A:$A,$B30,ARQUIVOS!$J:$J,"RECOMENDADA",ARQUIVOS!$K:$K,"Na pasta")&" de "&COUNTIFS(ARQUIVOS!$A:$A,$B30,ARQUIVOS!$J:$J,"RECOMENDADA") -> 0 de 3 | N30: =IF(L30>=K30,"SIM","NÃO") -> NÃO
A31: 28 | B31: 7898968541412 | C31: 1050 | D31: B0FH343T7F | E31: Ração Seca Natural Dots para Gatos Filhotes - Pacote 11 kg | F31: Ração | G31: Ração Seca Natural Dots para Gatos Filhotes | H31: 11 kg | I31: A | K31: =COUNTIFS(ARQUIVOS!$A:$A,$B31,ARQUIVOS!$J:$J,"SIM") -> 14 | L31: =COUNTIFS(ARQUIVOS!$A:$A,$B31,ARQUIVOS!$J:$J,"SIM",ARQUIVOS!$K:$K,"Na pasta") -> 0 | M31: =COUNTIFS(ARQUIVOS!$A:$A,$B31,ARQUIVOS!$J:$J,"RECOMENDADA",ARQUIVOS!$K:$K,"Na pasta")&" de "&COUNTIFS(ARQUIVOS!$A:$A,$B31,ARQUIVOS!$J:$J,"RECOMENDADA") -> 0 de 3 | N31: =IF(L31>=K31,"SIM","NÃO") -> NÃO
A32: 29 | B32: 7898968541405 | C32: 1074 | D32: B0FH35DMQ2 | E32: Ração Seca Natural Dots para Gatos Filhotes - Pacote 1 kg | F32: Ração | G32: Ração Seca Natural Dots para Gatos Filhotes | H32: 1 kg | I32: A | J32: 7898968541412 | K32: =COUNTIFS(ARQUIVOS!$A:$A,$B32,ARQUIVOS!$J:$J,"SIM") -> 7 | L32: =COUNTIFS(ARQUIVOS!$A:$A,$B32,ARQUIVOS!$J:$J,"SIM",ARQUIVOS!$K:$K,"Na pasta") -> 0 | M32: =COUNTIFS(ARQUIVOS!$A:$A,$B32,ARQUIVOS!$J:$J,"RECOMENDADA",ARQUIVOS!$K:$K,"Na pasta")&" de "&COUNTIFS(ARQUIVOS!$A:$A,$B32,ARQUIVOS!$J:$J,"RECOMENDADA") -> 0 de 3 | N32: =IF(L32>=K32,"SIM","NÃO") -> NÃO
A33: 30 | B33: 7908591301007 | C33: 1918 | D33: B0H3WVWSMC | E33: Ração Natural Dots Super Premium Cães Adultos Sabor Frango 2,5 kg | F33: Ração | H33: 2,5 kg | I33: A | K33: =COUNTIFS(ARQUIVOS!$A:$A,$B33,ARQUIVOS!$J:$J,"SIM") -> 14 | L33: =COUNTIFS(ARQUIVOS!$A:$A,$B33,ARQUIVOS!$J:$J,"SIM",ARQUIVOS!$K:$K,"Na pasta") -> 0 | M33: =COUNTIFS(ARQUIVOS!$A:$A,$B33,ARQUIVOS!$J:$J,"RECOMENDADA",ARQUIVOS!$K:$K,"Na pasta")&" de "&COUNTIFS(ARQUIVOS!$A:$A,$B33,ARQUIVOS!$J:$J,"RECOMENDADA") -> 0 de 3 | N33: =IF(L33>=K33,"SIM","NÃO") -> NÃO
A34: 31 | B34: 7908591301021 | C34: 1920 | D34: B0H3WSSZCB | E34: Ração Natural Dots Super Premium Cães Raças Pequenas Sabor Frango 1 kg | F34: Ração | H34: 1 kg | I34: A | K34: =COUNTIFS(ARQUIVOS!$A:$A,$B34,ARQUIVOS!$J:$J,"SIM") -> 14 | L34: =COUNTIFS(ARQUIVOS!$A:$A,$B34,ARQUIVOS!$J:$J,"SIM",ARQUIVOS!$K:$K,"Na pasta") -> 0 | M34: =COUNTIFS(ARQUIVOS!$A:$A,$B34,ARQUIVOS!$J:$J,"RECOMENDADA",ARQUIVOS!$K:$K,"Na pasta")&" de "&COUNTIFS(ARQUIVOS!$A:$A,$B34,ARQUIVOS!$J:$J,"RECOMENDADA") -> 0 de 3 | N34: =IF(L34>=K34,"SIM","NÃO") -> NÃO
A35: 32 | B35: 7908591301038 | C35: 1921 | D35: B0H3WP6GV3 | E35: Ração Natural Dots Super Premium Gatos Castrados Sabor Peixe 1 kg | F35: Ração | H35: 1 kg | I35: A | K35: =COUNTIFS(ARQUIVOS!$A:$A,$B35,ARQUIVOS!$J:$J,"SIM") -> 14 | L35: =COUNTIFS(ARQUIVOS!$A:$A,$B35,ARQUIVOS!$J:$J,"SIM",ARQUIVOS!$K:$K,"Na pasta") -> 0 | M35: =COUNTIFS(ARQUIVOS!$A:$A,$B35,ARQUIVOS!$J:$J,"RECOMENDADA",ARQUIVOS!$K:$K,"Na pasta")&" de "&COUNTIFS(ARQUIVOS!$A:$A,$B35,ARQUIVOS!$J:$J,"RECOMENDADA") -> 0 de 3 | N35: =IF(L35>=K35,"SIM","NÃO") -> NÃO
A36: 33 | B36: 7908591300147 | C36: 1197 | D36: B0FH3464Z6 | E36: Ração Seca Natural Dots Light para Cães - Pacote 1 kg | F36: Ração | H36: 1 kg | I36: A | K36: =COUNTIFS(ARQUIVOS!$A:$A,$B36,ARQUIVOS!$J:$J,"SIM") -> 14 | L36: =COUNTIFS(ARQUIVOS!$A:$A,$B36,ARQUIVOS!$J:$J,"SIM",ARQUIVOS!$K:$K,"Na pasta") -> 0 | M36: =COUNTIFS(ARQUIVOS!$A:$A,$B36,ARQUIVOS!$J:$J,"RECOMENDADA",ARQUIVOS!$K:$K,"Na pasta")&" de "&COUNTIFS(ARQUIVOS!$A:$A,$B36,ARQUIVOS!$J:$J,"RECOMENDADA") -> 0 de 3 | N36: =IF(L36>=K36,"SIM","NÃO") -> NÃO
A37: 34 | B37: 7908591300376 | C37: 1330 | D37: B0H3WXJWT1 | E37: Sachê Natural Dots Livre de Trangênico Cães Carne ao Molho 85 g | F37: Ração | H37: 85 g | I37: A | K37: =COUNTIFS(ARQUIVOS!$A:$A,$B37,ARQUIVOS!$J:$J,"SIM") -> 14 | L37: =COUNTIFS(ARQUIVOS!$A:$A,$B37,ARQUIVOS!$J:$J,"SIM",ARQUIVOS!$K:$K,"Na pasta") -> 0 | M37: =COUNTIFS(ARQUIVOS!$A:$A,$B37,ARQUIVOS!$J:$J,"RECOMENDADA",ARQUIVOS!$K:$K,"Na pasta")&" de "&COUNTIFS(ARQUIVOS!$A:$A,$B37,ARQUIVOS!$J:$J,"RECOMENDADA") -> 0 de 3 | N37: =IF(L37>=K37,"SIM","NÃO") -> NÃO
A38: 35 | B38: 7908591300383 | C38: 1331 | D38: B0H3WSGSKF | E38: Sachê Natural Dots Livre de Trangênico Cães Cordeiro 85 g | F38: Ração | H38: 85 g | I38: A | K38: =COUNTIFS(ARQUIVOS!$A:$A,$B38,ARQUIVOS!$J:$J,"SIM") -> 14 | L38: =COUNTIFS(ARQUIVOS!$A:$A,$B38,ARQUIVOS!$J:$J,"SIM",ARQUIVOS!$K:$K,"Na pasta") -> 0 | M38: =COUNTIFS(ARQUIVOS!$A:$A,$B38,ARQUIVOS!$J:$J,"RECOMENDADA",ARQUIVOS!$K:$K,"Na pasta")&" de "&COUNTIFS(ARQUIVOS!$A:$A,$B38,ARQUIVOS!$J:$J,"RECOMENDADA") -> 0 de 3 | N38: =IF(L38>=K38,"SIM","NÃO") -> NÃO
A39: 36 | B39: 7908591300390 | C39: 1332 | D39: B0H3WS6T81 | E39: Sachê Natural Dots Livre de Trangênico Gato Carne 85 g | F39: Ração | H39: 85 g | I39: A | K39: =COUNTIFS(ARQUIVOS!$A:$A,$B39,ARQUIVOS!$J:$J,"SIM") -> 14 | L39: =COUNTIFS(ARQUIVOS!$A:$A,$B39,ARQUIVOS!$J:$J,"SIM",ARQUIVOS!$K:$K,"Na pasta") -> 0 | M39: =COUNTIFS(ARQUIVOS!$A:$A,$B39,ARQUIVOS!$J:$J,"RECOMENDADA",ARQUIVOS!$K:$K,"Na pasta")&" de "&COUNTIFS(ARQUIVOS!$A:$A,$B39,ARQUIVOS!$J:$J,"RECOMENDADA") -> 0 de 3 | N39: =IF(L39>=K39,"SIM","NÃO") -> NÃO
A40: 37 | B40: 7908591300673 | C40: 1333 | D40: B0H3WK52X1 | E40: Sachê Natural Dots para Gatos Sabor Salmão 85 g - Livre de Transgênicos | F40: Ração | H40: 85 g | I40: A | K40: =COUNTIFS(ARQUIVOS!$A:$A,$B40,ARQUIVOS!$J:$J,"SIM") -> 14 | L40: =COUNTIFS(ARQUIVOS!$A:$A,$B40,ARQUIVOS!$J:$J,"SIM",ARQUIVOS!$K:$K,"Na pasta") -> 0 | M40: =COUNTIFS(ARQUIVOS!$A:$A,$B40,ARQUIVOS!$J:$J,"RECOMENDADA",ARQUIVOS!$K:$K,"Na pasta")&" de "&COUNTIFS(ARQUIVOS!$A:$A,$B40,ARQUIVOS!$J:$J,"RECOMENDADA") -> 0 de 3 | N40: =IF(L40>=K40,"SIM","NÃO") -> NÃO
...

Sheet ARQUIVOS
A1: ARQUIVOS · lista exata de imagens por produto. Copie o nome da coluna E e marque o Status quando a imagem estiver na pasta.
A2: Linhas com "NÃO" em Necessário? não precisam de arquivo (o produto usa o A+ de outro EAN, ou o código não existe no modelo escolhido).
A3: EAN | B3: Produto | C3: Peso / tamanho | D3: Código | E3: Nome exato do arquivo | F3: Onde entra | G3: O que mostrar | H3: Tamanho (px) | I3: Obrigatória? | J3: Necessário? | K3: Status | L3: Observações
A4: 7898968541504 | B4: =INDEX(PRODUTOS!$E$4:$E$63,MATCH($A4,PRODUTOS!$B$4:$B$63,0)) -> New Dots Ração Seca Premium para Cães Adultos - 15 kg | C4: =INDEX(PRODUTOS!$H$4:$H$63,MATCH($A4,PRODUTOS!$B$4:$B$63,0)) -> 15 kg | D4: MAIN | E4: =$A4&"."&$D4&".jpg" -> 7898968541504.MAIN.jpg | F4: =IF(INDEX(PRODUTOS!$I$4:$I$63,MATCH($A4,PRODUTOS!$B$4:$B$63,0))="B",INDEX(MODELOS!$F$3:$F$19,MATCH($D4,MODELOS!$A$3:$A$19,0)),INDEX(MODELOS!$B$3:$B$19,MATCH($D4,MODELOS!$A$3:$A$19,0))) -> Capa (posição 1) | G4: =IF(INDEX(PRODUTOS!$F$4:$F$63,MATCH($A4,PRODUTOS!$B$4:$B$63,0))="Ração",IF(INDEX(PRODUTOS!$I$4:$I$63,MATCH($A4,PRODUTOS!$B$4:$B$63,0))="B",INDEX(MODELOS!$G$3:$G$19,MATCH($D4,MODELOS!$A$3:$A$19,0)),INDEX(MODELOS!$C$3:$C$19,MATCH($D4,MODELOS!$A$3:$A$19,0))),IF(INDEX(PRODUTOS!$I$4:$I$63,MATCH($A4,PRODUTOS!$B$4:$B$63,0))="B",INDEX(MODELOS!$H$3:$H$19,MATCH($D4,MODELOS!$A$3:$A$19,0)),INDEX(MODELOS!$D$3:$D$19,MATCH($D4,MODELOS!$A$3:$A$19,0)))) -> Embalagem de frente, fundo branco puro, 85% da área, nada adicionado | H4: =IF(INDEX(PRODUTOS!$I$4:$I$63,MATCH($A4,PRODUTOS!$B$4:$B$63,0))="B",INDEX(MODELOS!$I$3:$I$19,MATCH($D4,MODELOS!$A$3:$A$19,0)),INDEX(MODELOS!$E$3:$E$19,MATCH($D4,MODELOS!$A$3:$A$19,0))) -> 2000 × 2000 | I4: =INDEX(MODELOS!$J$3:$J$19,MATCH($D4,MODELOS!$A$3:$A$19,0)) -> SIM | J4: =IF(LEFT($D4,2)<>"AP",IF($I4="SIM","SIM","RECOMENDADA"),IF(INDEX(PRODUTOS!$J$4:$J$63,MATCH($A4,PRODUTOS!$B$4:$B$63,0))<>"","NÃO (usa o A+ do EAN "&INDEX(PRODUTOS!$J$4:$J$63,MATCH($A4,PRODUTOS!$B$4:$B$63,0))&")",IF(AND(INDEX(PRODUTOS!$I$4:$I$63,MATCH($A4,PRODUTOS!$B$4:$B$63,0))="B",$D4="AP07"),"NÃO (modelo B)","SIM"))) -> SIM | K4: Pendente
A5: 7898968541504 | B5: =INDEX(PRODUTOS!$E$4:$E$63,MATCH($A5,PRODUTOS!$B$4:$B$63,0)) -> New Dots Ração Seca Premium para Cães Adultos - 15 kg | C5: =INDEX(PRODUTOS!$H$4:$H$63,MATCH($A5,PRODUTOS!$B$4:$B$63,0)) -> 15 kg | D5: PT01 | E5: =$A5&"."&$D5&".jpg" -> 7898968541504.PT01.jpg | F5: =IF(INDEX(PRODUTOS!$I$4:$I$63,MATCH($A5,PRODUTOS!$B$4:$B$63,0))="B",INDEX(MODELOS!$F$3:$F$19,MATCH($D5,MODELOS!$A$3:$A$19,0)),INDEX(MODELOS!$B$3:$B$19,MATCH($D5,MODELOS!$A$3:$A$19,0))) -> Galeria · posição 2 | G5: =IF(INDEX(PRODUTOS!$F$4:$F$63,MATCH($A5,PRODUTOS!$B$4:$B$63,0))="Ração",IF(INDEX(PRODUTOS!$I$4:$I$63,MATCH($A5,PRODUTOS!$B$4:$B$63,0))="B",INDEX(MODELOS!$G$3:$G$19,MATCH($D5,MODELOS!$A$3:$A$19,0)),INDEX(MODELOS!$C$3:$C$19,MATCH($D5,MODELOS!$A$3:$A$19,0))),IF(INDEX(PRODUTOS!$I$4:$I$63,MATCH($A5,PRODUTOS!$B$4:$B$63,0))="B",INDEX(MODELOS!$H$3:$H$19,MATCH($D5,MODELOS!$A$3:$A$19,0)),INDEX(MODELOS!$D$3:$D$19,MATCH($D5,MODELOS!$A$3:$A$19,0)))) -> Grande diferencial da linha (número ou promessa forte + grão e ingrediente) | H5: =IF(INDEX(PRODUTOS!$I$4:$I$63,MATCH($A5,PRODUTOS!$B$4:$B$63,0))="B",INDEX(MODELOS!$I$3:$I$19,MATCH($D5,MODELOS!$A$3:$A$19,0)),INDEX(MODELOS!$E$3:$E$19,MATCH($D5,MODELOS!$A$3:$A$19,0))) -> 2000 × 2000 | I5: =INDEX(MODELOS!$J$3:$J$19,MATCH($D5,MODELOS!$A$3:$A$19,0)) -> SIM | J5: =IF(LEFT($D5,2)<>"AP",IF($I5="SIM","SIM","RECOMENDADA"),IF(INDEX(PRODUTOS!$J$4:$J$63,MATCH($A5,PRODUTOS!$B$4:$B$63,0))<>"","NÃO (usa o A+ do EAN "&INDEX(PRODUTOS!$J$4:$J$63,MATCH($A5,PRODUTOS!$B$4:$B$63,0))&")",IF(AND(INDEX(PRODUTOS!$I$4:$I$63,MATCH($A5,PRODUTOS!$B$4:$B$63,0))="B",$D5="AP07"),"NÃO (modelo B)","SIM"))) -> SIM | K5: Pendente
A6: 7898968541504 | B6: =INDEX(PRODUTOS!$E$4:$E$63,MATCH($A6,PRODUTOS!$B$4:$B$63,0)) -> New Dots Ração Seca Premium para Cães Adultos - 15 kg | C6: =INDEX(PRODUTOS!$H$4:$H$63,MATCH($A6,PRODUTOS!$B$4:$B$63,0)) -> 15 kg | D6: PT02 | E6: =$A6&"."&$D6&".jpg" -> 7898968541504.PT02.jpg | F6: =IF(INDEX(PRODUTOS!$I$4:$I$63,MATCH($A6,PRODUTOS!$B$4:$B$63,0))="B",INDEX(MODELOS!$F$3:$F$19,MATCH($D6,MODELOS!$A$3:$A$19,0)),INDEX(MODELOS!$B$3:$B$19,MATCH($D6,MODELOS!$A$3:$A$19,0))) -> Galeria · posição 3 | G6: =IF(INDEX(PRODUTOS!$F$4:$F$63,MATCH($A6,PRODUTOS!$B$4:$B$63,0))="Ração",IF(INDEX(PRODUTOS!$I$4:$I$63,MATCH($A6,PRODUTOS!$B$4:$B$63,0))="B",INDEX(MODELOS!$G$3:$G$19,MATCH($D6,MODELOS!$A$3:$A$19,0)),INDEX(MODELOS!$C$3:$C$19,MATCH($D6,MODELOS!$A$3:$A$19,0))),IF(INDEX(PRODUTOS!$I$4:$I$63,MATCH($A6,PRODUTOS!$B$4:$B$63,0))="B",INDEX(MODELOS!$H$3:$H$19,MATCH($D6,MODELOS!$A$3:$A$19,0)),INDEX(MODELOS!$D$3:$D$19,MATCH($D6,MODELOS!$A$3:$A$19,0)))) -> Benefícios com ícones (4 a 6, impressos na embalagem) + ingrediente | H6: =IF(INDEX(PRODUTOS!$I$4:$I$63,MATCH($A6,PRODUTOS!$B$4:$B$63,0))="B",INDEX(MODELOS!$I$3:$I$19,MATCH($D6,MODELOS!$A$3:$A$19,0)),INDEX(MODELOS!$E$3:$E$19,MATCH($D6,MODELOS!$A$3:$A$19,0))) -> 2000 × 2000 | I6: =INDEX(MODELOS!$J$3:$J$19,MATCH($D6,MODELOS!$A$3:$A$19,0)) -> SIM | J6: =IF(LEFT($D6,2)<>"AP",IF($I6="SIM","SIM","RECOMENDADA"),IF(INDEX(PRODUTOS!$J$4:$J$63,MATCH($A6,PRODUTOS!$B$4:$B$63,0))<>"","NÃO (usa o A+ do EAN "&INDEX(PRODUTOS!$J$4:$J$63,MATCH($A6,PRODUTOS!$B$4:$B$63,0))&")",IF(AND(INDEX(PRODUTOS!$I$4:$I$63,MATCH($A6,PRODUTOS!$B$4:$B$63,0))="B",$D6="AP07"),"NÃO (modelo B)","SIM"))) -> SIM | K6: Pendente
A7: 7898968541504 | B7: =INDEX(PRODUTOS!$E$4:$E$63,MATCH($A7,PRODUTOS!$B$4:$B$63,0)) -> New Dots Ração Seca Premium para Cães Adultos - 15 kg | C7: =INDEX(PRODUTOS!$H$4:$H$63,MATCH($A7,PRODUTOS!$B$4:$B$63,0)) -> 15 kg | D7: PT03 | E7: =$A7&"."&$D7&".jpg" -> 7898968541504.PT03.jpg | F7: =IF(INDEX(PRODUTOS!$I$4:$I$63,MATCH($A7,PRODUTOS!$B$4:$B$63,0))="B",INDEX(MODELOS!$F$3:$F$19,MATCH($D7,MODELOS!$A$3:$A$19,0)),INDEX(MODELOS!$B$3:$B$19,MATCH($D7,MODELOS!$A$3:$A$19,0))) -> Galeria · posição 4 | G7: =IF(INDEX(PRODUTOS!$F$4:$F$63,MATCH($A7,PRODUTOS!$B$4:$B$63,0))="Ração",IF(INDEX(PRODUTOS!$I$4:$I$63,MATCH($A7,PRODUTOS!$B$4:$B$63,0))="B",INDEX(MODELOS!$G$3:$G$19,MATCH($D7,MODELOS!$A$3:$A$19,0)),INDEX(MODELOS!$C$3:$C$19,MATCH($D7,MODELOS!$A$3:$A$19,0))),IF(INDEX(PRODUTOS!$I$4:$I$63,MATCH($A7,PRODUTOS!$B$4:$B$63,0))="B",INDEX(MODELOS!$H$3:$H$19,MATCH($D7,MODELOS!$A$3:$A$19,0)),INDEX(MODELOS!$D$3:$D$19,MATCH($D7,MODELOS!$A$3:$A$19,0)))) -> Formato e tamanho do grão, com medida em mm e referência de tamanho | H7: =IF(INDEX(PRODUTOS!$I$4:$I$63,MATCH($A7,PRODUTOS!$B$4:$B$63,0))="B",INDEX(MODELOS!$I$3:$I$19,MATCH($D7,MODELOS!$A$3:$A$19,0)),INDEX(MODELOS!$E$3:$E$19,MATCH($D7,MODELOS!$A$3:$A$19,0))) -> 2000 × 2000 | I7: =INDEX(MODELOS!$J$3:$J$19,MATCH($D7,MODELOS!$A$3:$A$19,0)) -> SIM | J7: =IF(LEFT($D7,2)<>"AP",IF($I7="SIM","SIM","RECOMENDADA"),IF(INDEX(PRODUTOS!$J$4:$J$63,MATCH($A7,PRODUTOS!$B$4:$B$63,0))<>"","NÃO (usa o A+ do EAN "&INDEX(PRODUTOS!$J$4:$J$63,MATCH($A7,PRODUTOS!$B$4:$B$63,0))&")",IF(AND(INDEX(PRODUTOS!$I$4:$I$63,MATCH($A7,PRODUTOS!$B$4:$B$63,0))="B",$D7="AP07"),"NÃO (modelo B)","SIM"))) -> SIM | K7: Pendente
A8: 7898968541504 | B8: =INDEX(PRODUTOS!$E$4:$E$63,MATCH($A8,PRODUTOS!$B$4:$B$63,0)) -> New Dots Ração Seca Premium para Cães Adultos - 15 kg | C8: =INDEX(PRODUTOS!$H$4:$H$63,MATCH($A8,PRODUTOS!$B$4:$B$63,0)) -> 15 kg | D8: PT04 | E8: =$A8&"."&$D8&".jpg" -> 7898968541504.PT04.jpg | F8: =IF(INDEX(PRODUTOS!$I$4:$I$63,MATCH($A8,PRODUTOS!$B$4:$B$63,0))="B",INDEX(MODELOS!$F$3:$F$19,MATCH($D8,MODELOS!$A$3:$A$19,0)),INDEX(MODELOS!$B$3:$B$19,MATCH($D8,MODELOS!$A$3:$A$19,0))) -> Galeria · posição 5 | G8: =IF(INDEX(PRODUTOS!$F$4:$F$63,MATCH($A8,PRODUTOS!$B$4:$B$63,0))="Ração",IF(INDEX(PRODUTOS!$I$4:$I$63,MATCH($A8,PRODUTOS!$B$4:$B$63,0))="B",INDEX(MODELOS!$G$3:$G$19,MATCH($D8,MODELOS!$A$3:$A$19,0)),INDEX(MODELOS!$C$3:$C$19,MATCH($D8,MODELOS!$A$3:$A$19,0))),IF(INDEX(PRODUTOS!$I$4:$I$63,MATCH($A8,PRODUTOS!$B$4:$B$63,0))="B",INDEX(MODELOS!$H$3:$H$19,MATCH($D8,MODELOS!$A$3:$A$19,0)),INDEX(MODELOS!$D$3:$D$19,MATCH($D8,MODELOS!$A$3:$A$19,0)))) -> Quantidade diária por peso do cão/gato (números idênticos à embalagem) | H8: =IF(INDEX(PRODUTOS!$I$4:$I$63,MATCH($A8,PRODUTOS!$B$4:$B$63,0))="B",INDEX(MODELOS!$I$3:$I$19,MATCH($D8,MODELOS!$A$3:$A$19,0)),INDEX(MODELOS!$E$3:$E$19,MATCH($D8,MODELOS!$A$3:$A$19,0))) -> 2000 × 2000 | I8: =INDEX(MODELOS!$J$3:$J$19,MATCH($D8,MODELOS!$A$3:$A$19,0)) -> SIM | J8: =IF(LEFT($D8,2)<>"AP",IF($I8="SIM","SIM","RECOMENDADA"),IF(INDEX(PRODUTOS!$J$4:$J$63,MATCH($A8,PRODUTOS!$B$4:$B$63,0))<>"","NÃO (usa o A+ do EAN "&INDEX(PRODUTOS!$J$4:$J$63,MATCH($A8,PRODUTOS!$B$4:$B$63,0))&")",IF(AND(INDEX(PRODUTOS!$I$4:$I$63,MATCH($A8,PRODUTOS!$B$4:$B$63,0))="B",$D8="AP07"),"NÃO (modelo B)","SIM"))) -> SIM | K8: Pendente
A9: 7898968541504 | B9: =INDEX(PRODUTOS!$E$4:$E$63,MATCH($A9,PRODUTOS!$B$4:$B$63,0)) -> New Dots Ração Seca Premium para Cães Adultos - 15 kg | C9: =INDEX(PRODUTOS!$H$4:$H$63,MATCH($A9,PRODUTOS!$B$4:$B$63,0)) -> 15 kg | D9: PT05 | E9: =$A9&"."&$D9&".jpg" -> 7898968541504.PT05.jpg | F9: =IF(INDEX(PRODUTOS!$I$4:$I$63,MATCH($A9,PRODUTOS!$B$4:$B$63,0))="B",INDEX(MODELOS!$F$3:$F$19,MATCH($D9,MODELOS!$A$3:$A$19,0)),INDEX(MODELOS!$B$3:$B$19,MATCH($D9,MODELOS!$A$3:$A$19,0))) -> Galeria · posição 6 | G9: =IF(INDEX(PRODUTOS!$F$4:$F$63,MATCH($A9,PRODUTOS!$B$4:$B$63,0))="Ração",IF(INDEX(PRODUTOS!$I$4:$I$63,MATCH($A9,PRODUTOS!$B$4:$B$63,0))="B",INDEX(MODELOS!$G$3:$G$19,MATCH($D9,MODELOS!$A$3:$A$19,0)),INDEX(MODELOS!$C$3:$C$19,MATCH($D9,MODELOS!$A$3:$A$19,0))),IF(INDEX(PRODUTOS!$I$4:$I$63,MATCH($A9,PRODUTOS!$B$4:$B$63,0))="B",INDEX(MODELOS!$H$3:$H$19,MATCH($D9,MODELOS!$A$3:$A$19,0)),INDEX(MODELOS!$D$3:$D$19,MATCH($D9,MODELOS!$A$3:$A$19,0)))) -> Transição alimentar dia a dia (igual ao verso da embalagem) | H9: =IF(INDEX(PRODUTOS!$I$4:$I$63,MATCH($A9,PRODUTOS!$B$4:$B$63,0))="B",INDEX(MODELOS!$I$3:$I$19,MATCH($D9,MODELOS!$A$3:$A$19,0)),INDEX(MODELOS!$E$3:$E$19,MATCH($D9,MODELOS!$A$3:$A$19,0))) -> 2000 × 2000 | I9: =INDEX(MODELOS!$J$3:$J$19,MATCH($D9,MODELOS!$A$3:$A$19,0)) -> Recomendada | J9: =IF(LEFT($D9,2)<>"AP",IF($I9="SIM","SIM","RECOMENDADA"),IF(INDEX(PRODUTOS!$J$4:$J$63,MATCH($A9,PRODUTOS!$B$4:$B$63,0))<>"","NÃO (usa o A+ do EAN "&INDEX(PRODUTOS!$J$4:$J$63,MATCH($A9,PRODUTOS!$B$4:$B$63,0))&")",IF(AND(INDEX(PRODUTOS!$I$4:$I$63,MATCH($A9,PRODUTOS!$B$4:$B$63,0))="B",$D9="AP07"),"NÃO (modelo B)","SIM"))) -> RECOMENDADA | K9: Pendente
A10: 7898968541504 | B10: =INDEX(PRODUTOS!$E$4:$E$63,MATCH($A10,PRODUTOS!$B$4:$B$63,0)) -> New Dots Ração Seca Premium para Cães Adultos - 15 kg | C10: =INDEX(PRODUTOS!$H$4:$H$63,MATCH($A10,PRODUTOS!$B$4:$B$63,0)) -> 15 kg | D10: PT06 | E10: =$A10&"."&$D10&".jpg" -> 7898968541504.PT06.jpg | F10: =IF(INDEX(PRODUTOS!$I$4:$I$63,MATCH($A10,PRODUTOS!$B$4:$B$63,0))="B",INDEX(MODELOS!$F$3:$F$19,MATCH($D10,MODELOS!$A$3:$A$19,0)),INDEX(MODELOS!$B$3:$B$19,MATCH($D10,MODELOS!$A$3:$A$19,0))) -> Galeria · posição 7 | G10: =IF(INDEX(PRODUTOS!$F$4:$F$63,MATCH($A10,PRODUTOS!$B$4:$B$63,0))="Ração",IF(INDEX(PRODUTOS!$I$4:$I$63,MATCH($A10,PRODUTOS!$B$4:$B$63,0))="B",INDEX(MODELOS!$G$3:$G$19,MATCH($D10,MODELOS!$A$3:$A$19,0)),INDEX(MODELOS!$C$3:$C$19,MATCH($D10,MODELOS!$A$3:$A$19,0))),IF(INDEX(PRODUTOS!$I$4:$I$63,MATCH($A10,PRODUTOS!$B$4:$B$63,0))="B",INDEX(MODELOS!$H$3:$H$19,MATCH($D10,MODELOS!$A$3:$A$19,0)),INDEX(MODELOS!$D$3:$D$19,MATCH($D10,MODELOS!$A$3:$A$19,0)))) -> Composição e níveis de garantia em letra grande | H10: =IF(INDEX(PRODUTOS!$I$4:$I$63,MATCH($A10,PRODUTOS!$B$4:$B$63,0))="B",INDEX(MODELOS!$I$3:$I$19,MATCH($D10,MODELOS!$A$3:$A$19,0)),INDEX(MODELOS!$E$3:$E$19,MATCH($D10,MODELOS!$A$3:$A$19,0))) -> 2000 × 2000 | I10: =INDEX(MODELOS!$J$3:$J$19,MATCH($D10,MODELOS!$A$3:$A$19,0)) -> SIM | J10: =IF(LEFT($D10,2)<>"AP",IF($I10="SIM","SIM","RECOMENDADA"),IF(INDEX(PRODUTOS!$J$4:$J$63,MATCH($A10,PRODUTOS!$B$4:$B$63,0))<>"","NÃO (usa o A+ do EAN "&INDEX(PRODUTOS!$J$4:$J$63,MATCH($A10,PRODUTOS!$B$4:$B$63,0))&")",IF(AND(INDEX(PRODUTOS!$I$4:$I$63,MATCH($A10,PRODUTOS!$B$4:$B$63,0))="B",$D10="AP07"),"NÃO (modelo B)","SIM"))) -> SIM | K10: Pendente
A11: 7898968541504 | B11: =INDEX(PRODUTOS!$E$4:$E$63,MATCH($A11,PRODUTOS!$B$4:$B$63,0)) -> New Dots Ração Seca Premium para Cães Adultos - 15 kg | C11: =INDEX(PRODUTOS!$H$4:$H$63,MATCH($A11,PRODUTOS!$B$4:$B$63,0)) -> 15 kg | D11: PT07 | E11: =$A11&"."&$D11&".jpg" -> 7898968541504.PT07.jpg | F11: =IF(INDEX(PRODUTOS!$I$4:$I$63,MATCH($A11,PRODUTOS!$B$4:$B$63,0))="B",INDEX(MODELOS!$F$3:$F$19,MATCH($D11,MODELOS!$A$3:$A$19,0)),INDEX(MODELOS!$B$3:$B$19,MATCH($D11,MODELOS!$A$3:$A$19,0))) -> Galeria · posição 8 | G11: =IF(INDEX(PRODUTOS!$F$4:$F$63,MATCH($A11,PRODUTOS!$B$4:$B$63,0))="Ração",IF(INDEX(PRODUTOS!$I$4:$I$63,MATCH($A11,PRODUTOS!$B$4:$B$63,0))="B",INDEX(MODELOS!$G$3:$G$19,MATCH($D11,MODELOS!$A$3:$A$19,0)),INDEX(MODELOS!$C$3:$C$19,MATCH($D11,MODELOS!$A$3:$A$19,0))),IF(INDEX(PRODUTOS!$I$4:$I$63,MATCH($A11,PRODUTOS!$B$4:$B$63,0))="B",INDEX(MODELOS!$H$3:$H$19,MATCH($D11,MODELOS!$A$3:$A$19,0)),INDEX(MODELOS!$D$3:$D$19,MATCH($D11,MODELOS!$A$3:$A$19,0)))) -> Emocional / momento de uso (pet do porte certo, pote cheio) | H11: =IF(INDEX(PRODUTOS!$I$4:$I$63,MATCH($A11,PRODUTOS!$B$4:$B$63,0))="B",INDEX(MODELOS!$I$3:$I$19,MATCH($D11,MODELOS!$A$3:$A$19,0)),INDEX(MODELOS!$E$3:$E$19,MATCH($D11,MODELOS!$A$3:$A$19,0))) -> 2000 × 2000 | I11: =INDEX(MODELOS!$J$3:$J$19,MATCH($D11,MODELOS!$A$3:$A$19,0)) -> Recomendada | J11: =IF(LEFT($D11,2)<>"AP",IF($I11="SIM","SIM","RECOMENDADA"),IF(INDEX(PRODUTOS!$J$4:$J$63,MATCH($A11,PRODUTOS!$B$4:$B$63,0))<>"","NÃO (usa o A+ do EAN "&INDEX(PRODUTOS!$J$4:$J$63,MATCH($A11,PRODUTOS!$B$4:$B$63,0))&")",IF(AND(INDEX(PRODUTOS!$I$4:$I$63,MATCH($A11,PRODUTOS!$B$4:$B$63,0))="B",$D11="AP07"),"NÃO (modelo B)","SIM"))) -> RECOMENDADA | K11: Pendente
A12: 7898968541504 | B12: =INDEX(PRODUTOS!$E$4:$E$63,MATCH($A12,PRODUTOS!$B$4:$B$63,0)) -> New Dots Ração Seca Premium para Cães Adultos - 15 kg | C12: =INDEX(PRODUTOS!$H$4:$H$63,MATCH($A12,PRODUTOS!$B$4:$B$63,0)) -> 15 kg | D12: PT08 | E12: =$A12&"."&$D12&".jpg" -> 7898968541504.PT08.jpg | F12: =IF(INDEX(PRODUTOS!$I$4:$I$63,MATCH($A12,PRODUTOS!$B$4:$B$63,0))="B",INDEX(MODELOS!$F$3:$F$19,MATCH($D12,MODELOS!$A$3:$A$19,0)),INDEX(MODELOS!$B$3:$B$19,MATCH($D12,MODELOS!$A$3:$A$19,0))) -> Galeria · posição 9 | G12: =IF(INDEX(PRODUTOS!$F$4:$F$63,MATCH($A12,PRODUTOS!$B$4:$B$63,0))="Ração",IF(INDEX(PRODUTOS!$I$4:$I$63,MATCH($A12,PRODUTOS!$B$4:$B$63,0))="B",INDEX(MODELOS!$G$3:$G$19,MATCH($D12,MODELOS!$A$3:$A$19,0)),INDEX(MODELOS!$C$3:$C$19,MATCH($D12,MODELOS!$A$3:$A$19,0))),IF(INDEX(PRODUTOS!$I$4:$I$63,MATCH($A12,PRODUTOS!$B$4:$B$63,0))="B",INDEX(MODELOS!$H$3:$H$19,MATCH($D12,MODELOS!$A$3:$A$19,0)),INDEX(MODELOS!$D$3:$D$19,MATCH($D12,MODELOS!$A$3:$A$19,0)))) -> Linha da marca ou embalagem anterior × nova | H12: =IF(INDEX(PRODUTOS!$I$4:$I$63,MATCH($A12,PRODUTOS!$B$4:$B$63,0))="B",INDEX(MODELOS!$I$3:$I$19,MATCH($D12,MODELOS!$A$3:$A$19,0)),INDEX(MODELOS!$E$3:$E$19,MATCH($D12,MODELOS!$A$3:$A$19,0))) -> 2000 × 2000 | I12: =INDEX(MODELOS!$J$3:$J$19,MATCH($D12,MODELOS!$A$3:$A$19,0)) -> Recomendada | J12: =IF(LEFT($D12,2)<>"AP",IF($I12="SIM","SIM","RECOMENDADA"),IF(INDEX(PRODUTOS!$J$4:$J$63,MATCH($A12,PRODUTOS!$B$4:$B$63,0))<>"","NÃO (usa o A+ do EAN "&INDEX(PRODUTOS!$J$4:$J$63,MATCH($A12,PRODUTOS!$B$4:$B$63,0))&")",IF(AND(INDEX(PRODUTOS!$I$4:$I$63,MATCH($A12,PRODUTOS!$B$4:$B$63,0))="B",$D12="AP07"),"NÃO (modelo B)","SIM"))) -> RECOMENDADA | K12: Pendente
A13: 7898968541504 | B13: =INDEX(PRODUTOS!$E$4:$E$63,MATCH($A13,PRODUTOS!$B$4:$B$63,0)) -> New Dots Ração Seca Premium para Cães Adultos - 15 kg | C13: =INDEX(PRODUTOS!$H$4:$H$63,MATCH($A13,PRODUTOS!$B$4:$B$63,0)) -> 15 kg | D13: AP01 | E13: =$A13&"."&$D13&".jpg" -> 7898968541504.AP01.jpg | F13: =IF(INDEX(PRODUTOS!$I$4:$I$63,MATCH($A13,PRODUTOS!$B$4:$B$63,0))="B",INDEX(MODELOS!$F$3:$F$19,MATCH($D13,MODELOS!$A$3:$A$19,0)),INDEX(MODELOS!$B$3:$B$19,MATCH($D13,MODELOS!$A$3:$A$19,0))) -> A+ · Módulo 1 · Banner | G13: =IF(INDEX(PRODUTOS!$F$4:$F$63,MATCH($A13,PRODUTOS!$B$4:$B$63,0))="Ração",IF(INDEX(PRODUTOS!$I$4:$I$63,MATCH($A13,PRODUTOS!$B$4:$B$63,0))="B",INDEX(MODELOS!$G$3:$G$19,MATCH($D13,MODELOS!$A$3:$A$19,0)),INDEX(MODELOS!$C$3:$C$19,MATCH($D13,MODELOS!$A$3:$A$19,0))),IF(INDEX(PRODUTOS!$I$4:$I$63,MATCH($A13,PRODUTOS!$B$4:$B$63,0))="B",INDEX(MODELOS!$H$3:$H$19,MATCH($D13,MODELOS!$A$3:$A$19,0)),INDEX(MODELOS!$D$3:$D$19,MATCH($D13,MODELOS!$A$3:$A$19,0)))) -> Embalagem + pet + ingredientes, com o nome da linha | H13: =IF(INDEX(PRODUTOS!$I$4:$I$63,MATCH($A13,PRODUTOS!$B$4:$B$63,0))="B",INDEX(MODELOS!$I$3:$I$19,MATCH($D13,MODELOS!$A$3:$A$19,0)),INDEX(MODELOS!$E$3:$E$19,MATCH($D13,MODELOS!$A$3:$A$19,0))) -> 970 × 600 | I13: =INDEX(MODELOS!$J$3:$J$19,MATCH($D13,MODELOS!$A$3:$A$19,0)) -> Conforme modelo | J13: =IF(LEFT($D13,2)<>"AP",IF($I13="SIM","SIM","RECOMENDADA"),IF(INDEX(PRODUTOS!$J$4:$J$63,MATCH($A13,PRODUTOS!$B$4:$B$63,0))<>"","NÃO (usa o A+ do EAN "&INDEX(PRODUTOS!$J$4:$J$63,MATCH($A13,PRODUTOS!$B$4:$B$63,0))&")",IF(AND(INDEX(PRODUTOS!$I$4:$I$63,MATCH($A13,PRODUTOS!$B$4:$B$63,0))="B",$D13="AP07"),"NÃO (modelo B)","SIM"))) -> SIM | K13: Pendente
A14: 7898968541504 | B14: =INDEX(PRODUTOS!$E$4:$E$63,MATCH($A14,PRODUTOS!$B$4:$B$63,0)) -> New Dots Ração Seca Premium para Cães Adultos - 15 kg | C14: =INDEX(PRODUTOS!$H$4:$H$63,MATCH($A14,PRODUTOS!$B$4:$B$63,0)) -> 15 kg | D14: AP02 | E14: =$A14&"."&$D14&".jpg" -> 7898968541504.AP02.jpg | F14: =IF(INDEX(PRODUTOS!$I$4:$I$63,MATCH($A14,PRODUTOS!$B$4:$B$63,0))="B",INDEX(MODELOS!$F$3:$F$19,MATCH($D14,MODELOS!$A$3:$A$19,0)),INDEX(MODELOS!$B$3:$B$19,MATCH($D14,MODELOS!$A$3:$A$19,0))) -> A+ · Módulo 2 · Texto sobreposto | G14: =IF(INDEX(PRODUTOS!$F$4:$F$63,MATCH($A14,PRODUTOS!$B$4:$B$63,0))="Ração",IF(INDEX(PRODUTOS!$I$4:$I$63,MATCH($A14,PRODUTOS!$B$4:$B$63,0))="B",INDEX(MODELOS!$G$3:$G$19,MATCH($D14,MODELOS!$A$3:$A$19,0)),INDEX(MODELOS!$C$3:$C$19,MATCH($D14,MODELOS!$A$3:$A$19,0))),IF(INDEX(PRODUTOS!$I$4:$I$63,MATCH($A14,PRODUTOS!$B$4:$B$63,0))="B",INDEX(MODELOS!$H$3:$H$19,MATCH($D14,MODELOS!$A$3:$A$19,0)),INDEX(MODELOS!$D$3:$D$19,MATCH($D14,MODELOS!$A$3:$A$19,0)))) -> Principal diferencial; deixar o lado direito limpo | H14: =IF(INDEX(PRODUTOS!$I$4:$I$63,MATCH($A14,PRODUTOS!$B$4:$B$63,0))="B",INDEX(MODELOS!$I$3:$I$19,MATCH($D14,MODELOS!$A$3:$A$19,0)),INDEX(MODELOS!$E$3:$E$19,MATCH($D14,MODELOS!$A$3:$A$19,0))) -> 970 × 300 | I14: =INDEX(MODELOS!$J$3:$J$19,MATCH($D14,MODELOS!$A$3:$A$19,0)) -> Conforme modelo | J14: =IF(LEFT($D14,2)<>"AP",IF($I14="SIM","SIM","RECOMENDADA"),IF(INDEX(PRODUTOS!$J$4:$J$63,MATCH($A14,PRODUTOS!$B$4:$B$63,0))<>"","NÃO (usa o A+ do EAN "&INDEX(PRODUTOS!$J$4:$J$63,MATCH($A14,PRODUTOS!$B$4:$B$63,0))&")",IF(AND(INDEX(PRODUTOS!$I$4:$I$63,MATCH($A14,PRODUTOS!$B$4:$B$63,0))="B",$D14="AP07"),"NÃO (modelo B)","SIM"))) -> SIM | K14: Pendente
A15: 7898968541504 | B15: =INDEX(PRODUTOS!$E$4:$E$63,MATCH($A15,PRODUTOS!$B$4:$B$63,0)) -> New Dots Ração Seca Premium para Cães Adultos - 15 kg | C15: =INDEX(PRODUTOS!$H$4:$H$63,MATCH($A15,PRODUTOS!$B$4:$B$63,0)) -> 15 kg | D15: AP03 | E15: =$A15&"."&$D15&".jpg" -> 7898968541504.AP03.jpg | F15: =IF(INDEX(PRODUTOS!$I$4:$I$63,MATCH($A15,PRODUTOS!$B$4:$B$63,0))="B",INDEX(MODELOS!$F$3:$F$19,MATCH($D15,MODELOS!$A$3:$A$19,0)),INDEX(MODELOS!$B$3:$B$19,MATCH($D15,MODELOS!$A$3:$A$19,0))) -> A+ · Módulo 3 · Benefício 1 de 4 | G15: =IF(INDEX(PRODUTOS!$F$4:$F$63,MATCH($A15,PRODUTOS!$B$4:$B$63,0))="Ração",IF(INDEX(PRODUTOS!$I$4:$I$63,MATCH($A15,PRODUTOS!$B$4:$B$63,0))="B",INDEX(MODELOS!$G$3:$G$19,MATCH($D15,MODELOS!$A$3:$A$19,0)),INDEX(MODELOS!$C$3:$C$19,MATCH($D15,MODELOS!$A$3:$A$19,0))),IF(INDEX(PRODUTOS!$I$4:$I$63,MATCH($A15,PRODUTOS!$B$4:$B$63,0))="B",INDEX(MODELOS!$H$3:$H$19,MATCH($D15,MODELOS!$A$3:$A$19,0)),INDEX(MODELOS!$D$3:$D$19,MATCH($D15,MODELOS!$A$3:$A$19,0)))) -> Foto/ilustração do benefício 1 | H15: =IF(INDEX(PRODUTOS!$I$4:$I$63,MATCH($A15,PRODUTOS!$B$4:$B$63,0))="B",INDEX(MODELOS!$I$3:$I$19,MATCH($D15,MODELOS!$A$3:$A$19,0)),INDEX(MODELOS!$E$3:$E$19,MATCH($D15,MODELOS!$A$3:$A$19,0))) -> 220 × 200 | I15: =INDEX(MODELOS!$J$3:$J$19,MATCH($D15,MODELOS!$A$3:$A$19,0)) -> Conforme modelo | J15: =IF(LEFT($D15,2)<>"AP",IF($I15="SIM","SIM","RECOMENDADA"),IF(INDEX(PRODUTOS!$J$4:$J$63,MATCH($A15,PRODUTOS!$B$4:$B$63,0))<>"","NÃO (usa o A+ do EAN "&INDEX(PRODUTOS!$J$4:$J$63,MATCH($A15,PRODUTOS!$B$4:$B$63,0))&")",IF(AND(INDEX(PRODUTOS!$I$4:$I$63,MATCH($A15,PRODUTOS!$B$4:$B$63,0))="B",$D15="AP07"),"NÃO (modelo B)","SIM"))) -> SIM | K15: Pendente
... A1023: 7898968541979 | B1023: =INDEX(PRODUTOS!$E$4:$E$63,MATCH($A1023,PRODUTOS!$B$4:$B$63,0)) -> Tapete Higiênico Natural Dots Super Premium 80 x 60 cm com 7 Unidades | C1023: =INDEX(PRODUTOS!$H$4:$H$63,MATCH($A1023,PRODUTOS!$B$4:$B$63,0)) -> 7 un. | D1023: COMP | E1023: =$A1023&"."&$D1023&".jpg" -> 7898968541979.COMP.jpg | F1023: =IF(INDEX(PRODUTOS!$I$4:$I$63,MATCH($A1023,PRODUTOS!$B$4:$B$63,0))="B",INDEX(MODELOS!$F$3:$F$19,MATCH($D1023,MODELOS!$A$3:$A$19,0)),INDEX(MODELOS!$B$3:$B$19,MATCH($D1023,MODELOS!$A$3:$A$19,0))) -> A+ · Tabela comparativa | G1023: =IF(INDEX(PRODUTOS!$F$4:$F$63,MATCH($A1023,PRODUTOS!$B$4:$B$63,0))="Ração",IF(INDEX(PRODUTOS!$I$4:$I$63,MATCH($A1023,PRODUTOS!$B$4:$B$63,0))="B",INDEX(MODELOS!$G$3:$G$19,MATCH($D1023,MODELOS!$A$3:$A$19,0)),INDEX(MODELOS!$C$3:$C$19,MATCH($D1023,MODELOS!$A$3:$A$19,0))),IF(INDEX(PRODUTOS!$I$4:$I$63,MATCH($A1023,PRODUTOS!$B$4:$B$63,0))="B",INDEX(MODELOS!$H$3:$H$19,MATCH($D1023,MODELOS!$A$3:$A$19,0)),INDEX(MODELOS!$D$3:$D$19,MATCH($D1023,MODELOS!$A$3:$A$19,0)))) -> Produto na vertical, sem fundo colorido | H1023: =IF(INDEX(PRODUTOS!$I$4:$I$63,MATCH($A1023,PRODUTOS!$B$4:$B$63,0))="B",INDEX(MODELOS!$I$3:$I$19,MATCH($D1023,MODELOS!$A$3:$A$19,0)),INDEX(MODELOS!$E$3:$E$19,MATCH($D1023,MODELOS!$A$3:$A$19,0))) -> 150 × 300 | I1023: =INDEX(MODELOS!$J$3:$J$19,MATCH($D1023,MODELOS!$A$3:$A$19,0)) -> SIM | J1023: =IF(LEFT($D1023,2)<>"AP",IF($I1023="SIM","SIM","RECOMENDADA"),IF(INDEX(PRODUTOS!$J$4:$J$63,MATCH($A1023,PRODUTOS!$B$4:$B$63,0))<>"","NÃO (usa o A+ do EAN "&INDEX(PRODUTOS!$J$4:$J$63,MATCH($A1023,PRODUTOS!$B$4:$B$63,0))&")",IF(AND(INDEX(PRODUTOS!$I$4:$I$63,MATCH($A1023,PRODUTOS!$B$4:$B$63,0))="B",$D1023="AP07"),"NÃO (modelo B)","SIM"))) -> SIM | K1023: Pendente

Sheet MODELOS
A1: O que mostrar em cada arquivo · consulta (não alterar). Na galeria, os modelos A e B são iguais; mudam só as imagens do A+.
A2: Código | B2: Modelo A · Onde entra | C2: Modelo A · O que mostrar (Ração) | D2: Modelo A · O que mostrar (Petiscos e higiene) | E2: Modelo A · Tamanho (px) | F2: Modelo B · Onde entra | G2: Modelo B · O que mostrar (Ração) | H2: Modelo B · O que mostrar (Petiscos e higiene) | I2: Modelo B · Tamanho (px) | J2: Obrigatória?
A3: MAIN | B3: Capa (posição 1) | C3: Embalagem de frente, fundo branco puro, 85% da área, nada adicionado | D3: Embalagem de frente, fundo branco puro, 85% da área, nada adicionado | E3: 2000 × 2000 | F3: Capa (posição 1) | G3: Embalagem de frente, fundo branco puro, 85% da área, nada adicionado | H3: Embalagem de frente, fundo branco puro, 85% da área, nada adicionado | I3: 2000 × 2000 | J3: SIM
A4: PT01 | B4: Galeria · posição 2 | C4: Grande diferencial da linha (número ou promessa forte + grão e ingrediente) | D4: Grande diferencial (ex.: natural, biodegradável, perfumado) | E4: 2000 × 2000 | F4: Galeria · posição 2 | G4: Grande diferencial da linha (número ou promessa forte + grão e ingrediente) | H4: Grande diferencial (ex.: natural, biodegradável, perfumado) | I4: 2000 × 2000 | J4: SIM
A5: PT02 | B5: Galeria · posição 3 | C5: Benefícios com ícones (4 a 6, impressos na embalagem) + ingrediente | D5: Benefícios com ícones (4 a 6, impressos na embalagem) | E5: 2000 × 2000 | F5: Galeria · posição 3 | G5: Benefícios com ícones (4 a 6, impressos na embalagem) + ingrediente | H5: Benefícios com ícones (4 a 6, impressos na embalagem) | I5: 2000 × 2000 | J5: SIM
A6: PT03 | B6: Galeria · posição 4 | C6: Formato e tamanho do grão, com medida em mm e referência de tamanho | D6: Detalhe e tamanho real (petisco, grânulo ou tapete aberto), com medidas | E6: 2000 × 2000 | F6: Galeria · posição 4 | G6: Formato e tamanho do grão, com medida em mm e referência de tamanho | H6: Detalhe e tamanho real (petisco, grânulo ou tapete aberto), com medidas | I6: 2000 × 2000 | J6: SIM
A7: PT04 | B7: Galeria · posição 5 | C7: Quantidade diária por peso do cão/gato (números idênticos à embalagem) | D7: Modo de uso (como oferecer o petisco / como usar o produto) | E7: 2000 × 2000 | F7: Galeria · posição 5 | G7: Quantidade diária por peso do cão/gato (números idênticos à embalagem) | H7: Modo de uso (como oferecer o petisco / como usar o produto) | I7: 2000 × 2000 | J7: SIM
A8: PT05 | B8: Galeria · posição 6 | C8: Transição alimentar dia a dia (igual ao verso da embalagem) | D8: Quantidade por dia ou rendimento do pacote | E8: 2000 × 2000 | F8: Galeria · posição 6 | G8: Transição alimentar dia a dia (igual ao verso da embalagem) | H8: Quantidade por dia ou rendimento do pacote | I8: 2000 × 2000 | J8: Recomendada
A9: PT06 | B9: Galeria · posição 7 | C9: Composição e níveis de garantia em letra grande | D9: Composição/níveis de garantia (petiscos) ou especificações (higiene) | E9: 2000 × 2000 | F9: Galeria · posição 7 | G9: Composição e níveis de garantia em letra grande | H9: Composição/níveis de garantia (petiscos) ou especificações (higiene) | I9: 2000 × 2000 | J9: SIM
A10: PT07 | B10: Galeria · posição 8 | C10: Emocional / momento de uso (pet do porte certo, pote cheio) | D10: Emocional / momento de uso | E10: 2000 × 2000 | F10: Galeria · posição 8 | G10: Emocional / momento de uso (pet do porte certo, pote cheio) | H10: Emocional / momento de uso | I10: 2000 × 2000 | J10: Recomendada
A11: PT08 | B11: Galeria · posição 9 | C11: Linha da marca ou embalagem anterior × nova | D11: Linha da marca ("conheça também") | E11: 2000 × 2000 | F11: Galeria · posição 9 | G11: Linha da marca ou embalagem anterior × nova | H11: Linha da marca ("conheça também") | I11: 2000 × 2000 | J11: Recomendada
A12: AP01 | B12: A+ · Módulo 1 · Banner | C12: Embalagem + pet + ingredientes, com o nome da linha | D12: Produto + pet, com o nome da linha | E12: 970 × 600 | F12: A+ · Módulo 1 · Banner | G12: Cena principal da linha | H12: Cena principal da linha | I12: 970 × 600 | J12: Conforme modelo
A13: AP02 | B13: A+ · Módulo 2 · Texto sobreposto | C13: Principal diferencial; deixar o lado direito limpo | D13: Principal diferencial; deixar o lado direito limpo | E13: 970 × 300 | F13: A+ · Módulo 2 · Imagem com destaques | G13: Pacote ou grão em destaque | H13: Produto em destaque | I13: 300 × 300 | J13: Conforme modelo
... A19: COMP | B19: A+ · Tabela comparativa | C19: Pacote na vertical, sem fundo colorido | D19: Produto na vertical, sem fundo colorido | E19: 150 × 300 | F19: A+ · Tabela comparativa | G19: Pacote na vertical, sem fundo colorido | H19: Produto na vertical, sem fundo colorido | I19: 150 × 300 | J19: SIM
