Workbook

Sheet INSTRUÇÕES
B2: PLANILHA DE CONTROLE · IMAGENS DO A+ · NEW PET
B3: Produtos e EANs puxados do cadastro da New Pet na Amazon em 10/10/2026.
B5: Como usar
B6: 1. Pasta no Drive | C6: Coloque esta planilha dentro da pasta "NEWPET - IMAGENS A+" no Google Drive (pasta separada da do anúncio) e abra com Google Planilhas. Na mesma pasta ficam as imagens, sem subpastas.
B7: 2. Aba PRODUTOS | C7: Escolha o Modelo de A+ (A ou B) e confira a coluna "A+ igual ao EAN". Ela já vem sugerida: os tamanhos de um mesmo produto usam o A+ do maior tamanho. Apague o EAN da coluna para um produto ter A+ próprio.
B8: 3. Aba ARQUIVOS | C8: Lista exata das imagens de cada produto, com o nome pronto. Ela muda sozinha conforme o modelo escolhido e o A+ compartilhado. Linhas com "NÃO" em "Necessário?" não precisam de arquivo.
B9: 4. Aba MODELOS | C9: O que mostrar e o tamanho de cada imagem nos modelos A e B. Apenas consulta.
B10: 5. Avise a START | C10: Quando os produtos do lote estiverem com "Completo?" = SIM.
B12: Cores
B13: Amarelo | C13: Vocês preenchem ou escolhem (Modelo de A+, A+ igual ao EAN, Status e Observações).
B14: Cinza | C14: Dados do cadastro e fórmulas. Não alterar.
B16: Regras dos arquivos
B17: Nome | C17: EAN.CÓDIGO.jpg → exemplo: 7898968541504.AP01.jpg. Use exatamente o nome da aba ARQUIVOS.
B18: Imagem | C18: JPG ou PNG, cores RGB, no tamanho exato indicado (ou maior, na mesma proporção).
B19: Textos | C19: Títulos, parágrafos e descrições do A+ são criados pela START. De vocês, só as imagens (com, no máximo, um título curto desenhado).
B21: Atenção
B22: Palito 8" Rígido 10 un. | C22: Cadastrado na Amazon com código de 14 dígitos (17908591301158). Usar esse código no nome dos arquivos, exatamente como está na aba ARQUIVOS.

Sheet PRODUTOS
A1: PRODUTOS · New Pet · uma linha por produto à venda (cadastro Amazon em 10/10/2026)
A2: Amarelo = escolher/preencher · Cinza = cadastro e fórmulas. "A+ igual ao EAN" já vem sugerido; apague para o produto ter A+ próprio.
A3: Nº | B3: EAN | C3: SKU | D3: ASIN | E3: Produto (cadastro Amazon) | F3: Tipo | G3: Família (mesmo produto, outros tamanhos) | H3: Peso / tamanho | I3: Modelo de A+ | J3: A+ igual ao EAN | K3: Imagens necessárias | L3: Imagens na pasta | M3: Completo? | N3: Observações
A4: 1 | B4: 7898968541504 | C4: 7898968541504 | D4: B0H7LGC65H | E4: New Dots Ração Seca Premium para Cães Adultos - 15 kg | F4: Ração | G4: New Dots Ração Seca Premium para Cães Adultos | H4: 15 kg | I4: A | K4: =COUNTIFS(ARQUIVOS!$A:$A,$B4,ARQUIVOS!$I:$I,"SIM") -> 8 | L4: =COUNTIFS(ARQUIVOS!$A:$A,$B4,ARQUIVOS!$I:$I,"SIM",ARQUIVOS!$J:$J,"Na pasta") -> 0 | M4: =IF(L4>=K4,"SIM","NÃO") -> NÃO
A5: 2 | B5: 7908591301144 | C5: 7908591301144 | D5: B0H7L955P6 | E5: New Dots Ração Seca Premium para Cães Adultos - 10,1 kg | F5: Ração | G5: New Dots Ração Seca Premium para Cães Adultos | H5: 10,1 kg | I5: A | J5: 7898968541504 | K5: =COUNTIFS(ARQUIVOS!$A:$A,$B5,ARQUIVOS!$I:$I,"SIM") -> 1 | L5: =COUNTIFS(ARQUIVOS!$A:$A,$B5,ARQUIVOS!$I:$I,"SIM",ARQUIVOS!$J:$J,"Na pasta") -> 0 | M5: =IF(L5>=K5,"SIM","NÃO") -> NÃO
A6: 3 | B6: 7898968541467 | C6: 7898968541467 | D6: B0H7KXDGD7 | E6: New Dots Ração Seca Premium para Cães Adultos - 5 kg | F6: Ração | G6: New Dots Ração Seca Premium para Cães Adultos | H6: 5 kg | I6: A | J6: 7898968541504 | K6: =COUNTIFS(ARQUIVOS!$A:$A,$B6,ARQUIVOS!$I:$I,"SIM") -> 1 | L6: =COUNTIFS(ARQUIVOS!$A:$A,$B6,ARQUIVOS!$I:$I,"SIM",ARQUIVOS!$J:$J,"Na pasta") -> 0 | M6: =IF(L6>=K6,"SIM","NÃO") -> NÃO
A7: 4 | B7: 7898968541450 | C7: 7898968541450 | D7: B0H7KWY5KT | E7: New Dots Ração Seca Premium para Cães Adultos - 1 kg | F7: Ração | G7: New Dots Ração Seca Premium para Cães Adultos | H7: 1 kg | I7: A | J7: 7898968541504 | K7: =COUNTIFS(ARQUIVOS!$A:$A,$B7,ARQUIVOS!$I:$I,"SIM") -> 1 | L7: =COUNTIFS(ARQUIVOS!$A:$A,$B7,ARQUIVOS!$I:$I,"SIM",ARQUIVOS!$J:$J,"Na pasta") -> 0 | M7: =IF(L7>=K7,"SIM","NÃO") -> NÃO
A8: 5 | B8: 7898968541535 | C8: 7898968541535 | D8: B0H7LGV2SK | E8: New Dots Ração Seca Premium para Cães Adultos de Raças Pequenas - 20 kg | F8: Ração | G8: New Dots Ração Seca Premium para Cães Adultos de Raças Pequenas | H8: 20 kg | I8: A | K8: =COUNTIFS(ARQUIVOS!$A:$A,$B8,ARQUIVOS!$I:$I,"SIM") -> 8 | L8: =COUNTIFS(ARQUIVOS!$A:$A,$B8,ARQUIVOS!$I:$I,"SIM",ARQUIVOS!$J:$J,"Na pasta") -> 0 | M8: =IF(L8>=K8,"SIM","NÃO") -> NÃO
A9: 6 | B9: 7898968541528 | C9: 7898968541528 | D9: B0H7KZH2XV | E9: New Dots Ração Seca Premium para Cães Adultos de Raças Pequenas - 5 kg | F9: Ração | G9: New Dots Ração Seca Premium para Cães Adultos de Raças Pequenas | H9: 5 kg | I9: A | J9: 7898968541535 | K9: =COUNTIFS(ARQUIVOS!$A:$A,$B9,ARQUIVOS!$I:$I,"SIM") -> 1 | L9: =COUNTIFS(ARQUIVOS!$A:$A,$B9,ARQUIVOS!$I:$I,"SIM",ARQUIVOS!$J:$J,"Na pasta") -> 0 | M9: =IF(L9>=K9,"SIM","NÃO") -> NÃO
A10: 7 | B10: 7898968541511 | C10: 7898968541511 | D10: B0H7KZFSLZ | E10: New Dots Ração Seca Premium para Cães Adultos de Raças Pequenas - 1 kg | F10: Ração | G10: New Dots Ração Seca Premium para Cães Adultos de Raças Pequenas | H10: 1 kg | I10: A | J10: 7898968541535 | K10: =COUNTIFS(ARQUIVOS!$A:$A,$B10,ARQUIVOS!$I:$I,"SIM") -> 1 | L10: =COUNTIFS(ARQUIVOS!$A:$A,$B10,ARQUIVOS!$I:$I,"SIM",ARQUIVOS!$J:$J,"Na pasta") -> 0 | M10: =IF(L10>=K10,"SIM","NÃO") -> NÃO
A11: 8 | B11: 7898968541566 | C11: 7898968541566 | D11: B0H7L1QMMZ | E11: New Dots Ração Seca Premium para Cães Filhotes - 20 kg | F11: Ração | G11: New Dots Ração Seca Premium para Cães Filhotes | H11: 20 kg | I11: A | K11: =COUNTIFS(ARQUIVOS!$A:$A,$B11,ARQUIVOS!$I:$I,"SIM") -> 8 | L11: =COUNTIFS(ARQUIVOS!$A:$A,$B11,ARQUIVOS!$I:$I,"SIM",ARQUIVOS!$J:$J,"Na pasta") -> 0 | M11: =IF(L11>=K11,"SIM","NÃO") -> NÃO
A12: 9 | B12: 7898968541559 | C12: 7898968541559 | D12: B0H7LG9LK2 | E12: New Dots Ração Seca Premium para Cães Filhotes - 5 kg | F12: Ração | G12: New Dots Ração Seca Premium para Cães Filhotes | H12: 5 kg | I12: A | J12: 7898968541566 | K12: =COUNTIFS(ARQUIVOS!$A:$A,$B12,ARQUIVOS!$I:$I,"SIM") -> 1 | L12: =COUNTIFS(ARQUIVOS!$A:$A,$B12,ARQUIVOS!$I:$I,"SIM",ARQUIVOS!$J:$J,"Na pasta") -> 0 | M12: =IF(L12>=K12,"SIM","NÃO") -> NÃO
A13: 10 | B13: 7898968541542 | C13: 7898968541542 | D13: B0H7L3BHLH | E13: New Dots Ração Seca Premium para Cães Filhotes - 1 kg | F13: Ração | G13: New Dots Ração Seca Premium para Cães Filhotes | H13: 1 kg | I13: A | J13: 7898968541566 | K13: =COUNTIFS(ARQUIVOS!$A:$A,$B13,ARQUIVOS!$I:$I,"SIM") -> 1 | L13: =COUNTIFS(ARQUIVOS!$A:$A,$B13,ARQUIVOS!$I:$I,"SIM",ARQUIVOS!$J:$J,"Na pasta") -> 0 | M13: =IF(L13>=K13,"SIM","NÃO") -> NÃO
A14: 11 | B14: 7898968541597 | C14: 7898968541597 | D14: B0H7LG5GWZ | E14: New Dots Ração Seca Premium para Gatos Adultos - 20 kg | F14: Ração | G14: New Dots Ração Seca Premium para Gatos Adultos | H14: 20 kg | I14: A | K14: =COUNTIFS(ARQUIVOS!$A:$A,$B14,ARQUIVOS!$I:$I,"SIM") -> 8 | L14: =COUNTIFS(ARQUIVOS!$A:$A,$B14,ARQUIVOS!$I:$I,"SIM",ARQUIVOS!$J:$J,"Na pasta") -> 0 | M14: =IF(L14>=K14,"SIM","NÃO") -> NÃO
A15: 12 | B15: 7898968541573 | C15: 7898968541573 | D15: B0H7LD2TGC | E15: New Dots Ração Seca Premium para Gatos Adultos - 1 kg | F15: Ração | G15: New Dots Ração Seca Premium para Gatos Adultos | H15: 1 kg | I15: A | J15: 7898968541597 | K15: =COUNTIFS(ARQUIVOS!$A:$A,$B15,ARQUIVOS!$I:$I,"SIM") -> 1 | L15: =COUNTIFS(ARQUIVOS!$A:$A,$B15,ARQUIVOS!$I:$I,"SIM",ARQUIVOS!$J:$J,"Na pasta") -> 0 | M15: =IF(L15>=K15,"SIM","NÃO") -> NÃO
A16: 13 | B16: 7908591300666 | C16: 7908591300666 | D16: B0H7KWW8M4 | E16: New Dots Ração Seca Premium para Gatos Adultos Castrados - 20 kg | F16: Ração | G16: New Dots Ração Seca Premium para Gatos Adultos Castrados | H16: 20 kg | I16: A | K16: =COUNTIFS(ARQUIVOS!$A:$A,$B16,ARQUIVOS!$I:$I,"SIM") -> 8 | L16: =COUNTIFS(ARQUIVOS!$A:$A,$B16,ARQUIVOS!$I:$I,"SIM",ARQUIVOS!$J:$J,"Na pasta") -> 0 | M16: =IF(L16>=K16,"SIM","NÃO") -> NÃO
A17: 14 | B17: 7908591300413 | C17: 7908591300413 | D17: B0H7L2N7GF | E17: New Dots Ração Seca Premium para Gatos Adultos Castrados - 11 kg | F17: Ração | G17: New Dots Ração Seca Premium para Gatos Adultos Castrados | H17: 11 kg | I17: A | J17: 7908591300666 | K17: =COUNTIFS(ARQUIVOS!$A:$A,$B17,ARQUIVOS!$I:$I,"SIM") -> 1 | L17: =COUNTIFS(ARQUIVOS!$A:$A,$B17,ARQUIVOS!$I:$I,"SIM",ARQUIVOS!$J:$J,"Na pasta") -> 0 | M17: =IF(L17>=K17,"SIM","NÃO") -> NÃO
A18: 15 | B18: 7908591300406 | C18: 7908591300406 | D18: B0H7KWTZ9P | E18: New Dots Ração Seca Premium para Gatos Adultos Castrados - 1 kg | F18: Ração | G18: New Dots Ração Seca Premium para Gatos Adultos Castrados | H18: 1 kg | I18: A | J18: 7908591300666 | K18: =COUNTIFS(ARQUIVOS!$A:$A,$B18,ARQUIVOS!$I:$I,"SIM") -> 1 | L18: =COUNTIFS(ARQUIVOS!$A:$A,$B18,ARQUIVOS!$I:$I,"SIM",ARQUIVOS!$J:$J,"Na pasta") -> 0 | M18: =IF(L18>=K18,"SIM","NÃO") -> NÃO
A19: 16 | B19: 7898968541283 | C19: 1001 | D19: B0FH32BP56 | E19: Ração Seca Natural Dots para Cães Adultos - Pacote 15 kg | F19: Ração | G19: Ração Seca Natural Dots para Cães Adultos | H19: 15 kg | I19: A | K19: =COUNTIFS(ARQUIVOS!$A:$A,$B19,ARQUIVOS!$I:$I,"SIM") -> 8 | L19: =COUNTIFS(ARQUIVOS!$A:$A,$B19,ARQUIVOS!$I:$I,"SIM",ARQUIVOS!$J:$J,"Na pasta") -> 0 | M19: =IF(L19>=K19,"SIM","NÃO") -> NÃO
A20: 17 | B20: 7898968541269 | C20: 1195 | D20: B0FH347L7H | E20: Ração Seca Natural Dots para Cães Adultos - Pacote 1 kg | F20: Ração | G20: Ração Seca Natural Dots para Cães Adultos | H20: 1 kg | I20: A | J20: 7898968541283 | K20: =COUNTIFS(ARQUIVOS!$A:$A,$B20,ARQUIVOS!$I:$I,"SIM") -> 1 | L20: =COUNTIFS(ARQUIVOS!$A:$A,$B20,ARQUIVOS!$I:$I,"SIM",ARQUIVOS!$J:$J,"Na pasta") -> 0 | M20: =IF(L20>=K20,"SIM","NÃO") -> NÃO
A21: 18 | B21: 7898968541313 | C21: 1075 | D21: B0FH34VLTD | E21: Ração Seca Natural Dots para Cães Filhotes - Pacote 15 kg | F21: Ração | G21: Ração Seca Natural Dots para Cães Filhotes | H21: 15 kg | I21: A | K21: =COUNTIFS(ARQUIVOS!$A:$A,$B21,ARQUIVOS!$I:$I,"SIM") -> 8 | L21: =COUNTIFS(ARQUIVOS!$A:$A,$B21,ARQUIVOS!$I:$I,"SIM",ARQUIVOS!$J:$J,"Na pasta") -> 0 | M21: =IF(L21>=K21,"SIM","NÃO") -> NÃO
A22: 19 | B22: 7898968541290 | C22: 1070 | D22: B0FH2ZVVMK | E22: Ração Seca Natural Dots para Cães Filhotes - Pacote 1 kg | F22: Ração | G22: Ração Seca Natural Dots para Cães Filhotes | H22: 1 kg | I22: A | J22: 7898968541313 | K22: =COUNTIFS(ARQUIVOS!$A:$A,$B22,ARQUIVOS!$I:$I,"SIM") -> 1 | L22: =COUNTIFS(ARQUIVOS!$A:$A,$B22,ARQUIVOS!$I:$I,"SIM",ARQUIVOS!$J:$J,"Na pasta") -> 0 | M22: =IF(L22>=K22,"SIM","NÃO") -> NÃO
A23: 20 | B23: 7898968541276 | C23: 1199 | D23: B0FH337MZK | E23: Ração Seca Natural Dots para Cães Sênior - Pacote 15 kg | F23: Ração | G23: Ração Seca Natural Dots para Cães Sênior | H23: 15 kg | I23: A | K23: =COUNTIFS(ARQUIVOS!$A:$A,$B23,ARQUIVOS!$I:$I,"SIM") -> 8 | L23: =COUNTIFS(ARQUIVOS!$A:$A,$B23,ARQUIVOS!$I:$I,"SIM",ARQUIVOS!$J:$J,"Na pasta") -> 0 | M23: =IF(L23>=K23,"SIM","NÃO") -> NÃO
A24: 21 | B24: 7908591300154 | C24: 1198 | D24: B0FH341T47 | E24: Ração Seca Natural Dots para Cães Sênior - Pacote 1 kg | F24: Ração | G24: Ração Seca Natural Dots para Cães Sênior | H24: 1 kg | I24: A | J24: 7898968541276 | K24: =COUNTIFS(ARQUIVOS!$A:$A,$B24,ARQUIVOS!$I:$I,"SIM") -> 1 | L24: =COUNTIFS(ARQUIVOS!$A:$A,$B24,ARQUIVOS!$I:$I,"SIM",ARQUIVOS!$J:$J,"Na pasta") -> 0 | M24: =IF(L24>=K24,"SIM","NÃO") -> NÃO
A25: 22 | B25: 7898968541344 | C25: 1196 | D25: B0FH31K58G | E25: Ração Seca Natural Dots para Cães de Raças Pequenas - Pacote 15 kg | F25: Ração | G25: Ração Seca Natural Dots para Cães de Raças Pequenas | H25: 15 kg | I25: A | K25: =COUNTIFS(ARQUIVOS!$A:$A,$B25,ARQUIVOS!$I:$I,"SIM") -> 8 | L25: =COUNTIFS(ARQUIVOS!$A:$A,$B25,ARQUIVOS!$I:$I,"SIM",ARQUIVOS!$J:$J,"Na pasta") -> 0 | M25: =IF(L25>=K25,"SIM","NÃO") -> NÃO
A26: 23 | B26: 7898968541320 | C26: 1071 | D26: B0FH31X2DG | E26: Ração Seca Natural Dots para Cães de Raças Pequenas - Pacote 1 kg | F26: Ração | G26: Ração Seca Natural Dots para Cães de Raças Pequenas | H26: 1 kg | I26: A | J26: 7898968541344 | K26: =COUNTIFS(ARQUIVOS!$A:$A,$B26,ARQUIVOS!$I:$I,"SIM") -> 1 | L26: =COUNTIFS(ARQUIVOS!$A:$A,$B26,ARQUIVOS!$I:$I,"SIM",ARQUIVOS!$J:$J,"Na pasta") -> 0 | M26: =IF(L26>=K26,"SIM","NÃO") -> NÃO
A27: 24 | B27: 7898968541382 | C27: 1081 | D27: B0FH34LMJT | E27: Ração Seca Natural Dots para Gatos Adultos - Pacote 11 kg | F27: Ração | G27: Ração Seca Natural Dots para Gatos Adultos | H27: 11 kg | I27: A | K27: =COUNTIFS(ARQUIVOS!$A:$A,$B27,ARQUIVOS!$I:$I,"SIM") -> 8 | L27: =COUNTIFS(ARQUIVOS!$A:$A,$B27,ARQUIVOS!$I:$I,"SIM",ARQUIVOS!$J:$J,"Na pasta") -> 0 | M27: =IF(L27>=K27,"SIM","NÃO") -> NÃO
A28: 25 | B28: 7898968541368 | C28: 1080 | D28: B0FH33YSNK | E28: Ração Seca Natural Dots para Gatos Adultos - Pacote 1 kg | F28: Ração | G28: Ração Seca Natural Dots para Gatos Adultos | H28: 1 kg | I28: A | J28: 7898968541382 | K28: =COUNTIFS(ARQUIVOS!$A:$A,$B28,ARQUIVOS!$I:$I,"SIM") -> 1 | L28: =COUNTIFS(ARQUIVOS!$A:$A,$B28,ARQUIVOS!$I:$I,"SIM",ARQUIVOS!$J:$J,"Na pasta") -> 0 | M28: =IF(L28>=K28,"SIM","NÃO") -> NÃO
A29: 26 | B29: 7898968541399 | C29: 1083 | D29: B0FH34NGCJ | E29: Ração Seca Natural Dots para Gatos Castrados - Pacote 11 kg | F29: Ração | G29: Ração Seca Natural Dots para Gatos Castrados | H29: 11 kg | I29: A | K29: =COUNTIFS(ARQUIVOS!$A:$A,$B29,ARQUIVOS!$I:$I,"SIM") -> 8 | L29: =COUNTIFS(ARQUIVOS!$A:$A,$B29,ARQUIVOS!$I:$I,"SIM",ARQUIVOS!$J:$J,"Na pasta") -> 0 | M29: =IF(L29>=K29,"SIM","NÃO") -> NÃO
A30: 27 | B30: 7898968541375 | C30: 1073 | D30: B0FH32M1DZ | E30: Ração Seca Natural Dots para Gatos Castrados - Pacote 1 kg | F30: Ração | G30: Ração Seca Natural Dots para Gatos Castrados | H30: 1 kg | I30: A | J30: 7898968541399 | K30: =COUNTIFS(ARQUIVOS!$A:$A,$B30,ARQUIVOS!$I:$I,"SIM") -> 1 | L30: =COUNTIFS(ARQUIVOS!$A:$A,$B30,ARQUIVOS!$I:$I,"SIM",ARQUIVOS!$J:$J,"Na pasta") -> 0 | M30: =IF(L30>=K30,"SIM","NÃO") -> NÃO
A31: 28 | B31: 7898968541412 | C31: 1050 | D31: B0FH343T7F | E31: Ração Seca Natural Dots para Gatos Filhotes - Pacote 11 kg | F31: Ração | G31: Ração Seca Natural Dots para Gatos Filhotes | H31: 11 kg | I31: A | K31: =COUNTIFS(ARQUIVOS!$A:$A,$B31,ARQUIVOS!$I:$I,"SIM") -> 8 | L31: =COUNTIFS(ARQUIVOS!$A:$A,$B31,ARQUIVOS!$I:$I,"SIM",ARQUIVOS!$J:$J,"Na pasta") -> 0 | M31: =IF(L31>=K31,"SIM","NÃO") -> NÃO
A32: 29 | B32: 7898968541405 | C32: 1074 | D32: B0FH35DMQ2 | E32: Ração Seca Natural Dots para Gatos Filhotes - Pacote 1 kg | F32: Ração | G32: Ração Seca Natural Dots para Gatos Filhotes | H32: 1 kg | I32: A | J32: 7898968541412 | K32: =COUNTIFS(ARQUIVOS!$A:$A,$B32,ARQUIVOS!$I:$I,"SIM") -> 1 | L32: =COUNTIFS(ARQUIVOS!$A:$A,$B32,ARQUIVOS!$I:$I,"SIM",ARQUIVOS!$J:$J,"Na pasta") -> 0 | M32: =IF(L32>=K32,"SIM","NÃO") -> NÃO
A33: 30 | B33: 7908591301007 | C33: 1918 | D33: B0H3WVWSMC | E33: Ração Natural Dots Super Premium Cães Adultos Sabor Frango 2,5 kg | F33: Ração | H33: 2,5 kg | I33: A | K33: =COUNTIFS(ARQUIVOS!$A:$A,$B33,ARQUIVOS!$I:$I,"SIM") -> 8 | L33: =COUNTIFS(ARQUIVOS!$A:$A,$B33,ARQUIVOS!$I:$I,"SIM",ARQUIVOS!$J:$J,"Na pasta") -> 0 | M33: =IF(L33>=K33,"SIM","NÃO") -> NÃO
A34: 31 | B34: 7908591301021 | C34: 1920 | D34: B0H3WSSZCB | E34: Ração Natural Dots Super Premium Cães Raças Pequenas Sabor Frango 1 kg | F34: Ração | H34: 1 kg | I34: A | K34: =COUNTIFS(ARQUIVOS!$A:$A,$B34,ARQUIVOS!$I:$I,"SIM") -> 8 | L34: =COUNTIFS(ARQUIVOS!$A:$A,$B34,ARQUIVOS!$I:$I,"SIM",ARQUIVOS!$J:$J,"Na pasta") -> 0 | M34: =IF(L34>=K34,"SIM","NÃO") -> NÃO
A35: 32 | B35: 7908591301038 | C35: 1921 | D35: B0H3WP6GV3 | E35: Ração Natural Dots Super Premium Gatos Castrados Sabor Peixe 1 kg | F35: Ração | H35: 1 kg | I35: A | K35: =COUNTIFS(ARQUIVOS!$A:$A,$B35,ARQUIVOS!$I:$I,"SIM") -> 8 | L35: =COUNTIFS(ARQUIVOS!$A:$A,$B35,ARQUIVOS!$I:$I,"SIM",ARQUIVOS!$J:$J,"Na pasta") -> 0 | M35: =IF(L35>=K35,"SIM","NÃO") -> NÃO
A36: 33 | B36: 7908591300147 | C36: 1197 | D36: B0FH3464Z6 | E36: Ração Seca Natural Dots Light para Cães - Pacote 1 kg | F36: Ração | H36: 1 kg | I36: A | K36: =COUNTIFS(ARQUIVOS!$A:$A,$B36,ARQUIVOS!$I:$I,"SIM") -> 8 | L36: =COUNTIFS(ARQUIVOS!$A:$A,$B36,ARQUIVOS!$I:$I,"SIM",ARQUIVOS!$J:$J,"Na pasta") -> 0 | M36: =IF(L36>=K36,"SIM","NÃO") -> NÃO
A37: 34 | B37: 7908591300376 | C37: 1330 | D37: B0H3WXJWT1 | E37: Sachê Natural Dots Livre de Trangênico Cães Carne ao Molho 85 g | F37: Ração | H37: 85 g | I37: A | K37: =COUNTIFS(ARQUIVOS!$A:$A,$B37,ARQUIVOS!$I:$I,"SIM") -> 8 | L37: =COUNTIFS(ARQUIVOS!$A:$A,$B37,ARQUIVOS!$I:$I,"SIM",ARQUIVOS!$J:$J,"Na pasta") -> 0 | M37: =IF(L37>=K37,"SIM","NÃO") -> NÃO
A38: 35 | B38: 7908591300383 | C38: 1331 | D38: B0H3WSGSKF | E38: Sachê Natural Dots Livre de Trangênico Cães Cordeiro 85 g | F38: Ração | H38: 85 g | I38: A | K38: =COUNTIFS(ARQUIVOS!$A:$A,$B38,ARQUIVOS!$I:$I,"SIM") -> 8 | L38: =COUNTIFS(ARQUIVOS!$A:$A,$B38,ARQUIVOS!$I:$I,"SIM",ARQUIVOS!$J:$J,"Na pasta") -> 0 | M38: =IF(L38>=K38,"SIM","NÃO") -> NÃO
A39: 36 | B39: 7908591300390 | C39: 1332 | D39: B0H3WS6T81 | E39: Sachê Natural Dots Livre de Trangênico Gato Carne 85 g | F39: Ração | H39: 85 g | I39: A | K39: =COUNTIFS(ARQUIVOS!$A:$A,$B39,ARQUIVOS!$I:$I,"SIM") -> 8 | L39: =COUNTIFS(ARQUIVOS!$A:$A,$B39,ARQUIVOS!$I:$I,"SIM",ARQUIVOS!$J:$J,"Na pasta") -> 0 | M39: =IF(L39>=K39,"SIM","NÃO") -> NÃO
A40: 37 | B40: 7908591300673 | C40: 1333 | D40: B0H3WK52X1 | E40: Sachê Natural Dots para Gatos Sabor Salmão 85 g - Livre de Transgênicos | F40: Ração | H40: 85 g | I40: A | K40: =COUNTIFS(ARQUIVOS!$A:$A,$B40,ARQUIVOS!$I:$I,"SIM") -> 8 | L40: =COUNTIFS(ARQUIVOS!$A:$A,$B40,ARQUIVOS!$I:$I,"SIM",ARQUIVOS!$J:$J,"Na pasta") -> 0 | M40: =IF(L40>=K40,"SIM","NÃO") -> NÃO
...

Sheet ARQUIVOS
A1: ARQUIVOS · lista exata de imagens do A+ por produto
A2: Linhas com "NÃO" em Necessário? não precisam de arquivo (o produto usa o A+ de outro EAN, ou o código não existe no modelo escolhido).
A3: EAN | B3: Produto | C3: Peso / tamanho | D3: Código | E3: Nome exato do arquivo | F3: Onde entra | G3: O que mostrar | H3: Tamanho (px) | I3: Necessário? | J3: Status | K3: Observações
A4: 7898968541504 | B4: =INDEX(PRODUTOS!$E$4:$E$63,MATCH($A4,PRODUTOS!$B$4:$B$63,0)) -> New Dots Ração Seca Premium para Cães Adultos - 15 kg | C4: =INDEX(PRODUTOS!$H$4:$H$63,MATCH($A4,PRODUTOS!$B$4:$B$63,0)) -> 15 kg | D4: AP01 | E4: =$A4&"."&$D4&".jpg" -> 7898968541504.AP01.jpg | F4: =IF(INDEX(PRODUTOS!$I$4:$I$63,MATCH($A4,PRODUTOS!$B$4:$B$63,0))="B",INDEX(MODELOS!$F$4:$F$11,MATCH($D4,MODELOS!$A$4:$A$11,0)),INDEX(MODELOS!$B$4:$B$11,MATCH($D4,MODELOS!$A$4:$A$11,0))) -> Módulo 1 · Banner | G4: =IF(INDEX(PRODUTOS!$F$4:$F$63,MATCH($A4,PRODUTOS!$B$4:$B$63,0))="Ração",IF(INDEX(PRODUTOS!$I$4:$I$63,MATCH($A4,PRODUTOS!$B$4:$B$63,0))="B",INDEX(MODELOS!$G$4:$G$11,MATCH($D4,MODELOS!$A$4:$A$11,0)),INDEX(MODELOS!$C$4:$C$11,MATCH($D4,MODELOS!$A$4:$A$11,0))),IF(INDEX(PRODUTOS!$I$4:$I$63,MATCH($A4,PRODUTOS!$B$4:$B$63,0))="B",INDEX(MODELOS!$H$4:$H$11,MATCH($D4,MODELOS!$A$4:$A$11,0)),INDEX(MODELOS!$D$4:$D$11,MATCH($D4,MODELOS!$A$4:$A$11,0)))) -> Embalagem + pet + ingredientes, com o nome da linha | H4: =IF(INDEX(PRODUTOS!$I$4:$I$63,MATCH($A4,PRODUTOS!$B$4:$B$63,0))="B",INDEX(MODELOS!$I$4:$I$11,MATCH($D4,MODELOS!$A$4:$A$11,0)),INDEX(MODELOS!$E$4:$E$11,MATCH($D4,MODELOS!$A$4:$A$11,0))) -> 970 × 600 | I4: =IF($D4="COMP","SIM",IF(INDEX(PRODUTOS!$J$4:$J$63,MATCH($A4,PRODUTOS!$B$4:$B$63,0))<>"","NÃO (usa o A+ do EAN "&INDEX(PRODUTOS!$J$4:$J$63,MATCH($A4,PRODUTOS!$B$4:$B$63,0))&")",IF(AND(INDEX(PRODUTOS!$I$4:$I$63,MATCH($A4,PRODUTOS!$B$4:$B$63,0))="B",$D4="AP07"),"NÃO (modelo B)","SIM"))) -> SIM | J4: Pendente
A5: 7898968541504 | B5: =INDEX(PRODUTOS!$E$4:$E$63,MATCH($A5,PRODUTOS!$B$4:$B$63,0)) -> New Dots Ração Seca Premium para Cães Adultos - 15 kg | C5: =INDEX(PRODUTOS!$H$4:$H$63,MATCH($A5,PRODUTOS!$B$4:$B$63,0)) -> 15 kg | D5: AP02 | E5: =$A5&"."&$D5&".jpg" -> 7898968541504.AP02.jpg | F5: =IF(INDEX(PRODUTOS!$I$4:$I$63,MATCH($A5,PRODUTOS!$B$4:$B$63,0))="B",INDEX(MODELOS!$F$4:$F$11,MATCH($D5,MODELOS!$A$4:$A$11,0)),INDEX(MODELOS!$B$4:$B$11,MATCH($D5,MODELOS!$A$4:$A$11,0))) -> Módulo 2 · Texto sobreposto | G5: =IF(INDEX(PRODUTOS!$F$4:$F$63,MATCH($A5,PRODUTOS!$B$4:$B$63,0))="Ração",IF(INDEX(PRODUTOS!$I$4:$I$63,MATCH($A5,PRODUTOS!$B$4:$B$63,0))="B",INDEX(MODELOS!$G$4:$G$11,MATCH($D5,MODELOS!$A$4:$A$11,0)),INDEX(MODELOS!$C$4:$C$11,MATCH($D5,MODELOS!$A$4:$A$11,0))),IF(INDEX(PRODUTOS!$I$4:$I$63,MATCH($A5,PRODUTOS!$B$4:$B$63,0))="B",INDEX(MODELOS!$H$4:$H$11,MATCH($D5,MODELOS!$A$4:$A$11,0)),INDEX(MODELOS!$D$4:$D$11,MATCH($D5,MODELOS!$A$4:$A$11,0)))) -> Principal diferencial; deixar o lado direito limpo | H5: =IF(INDEX(PRODUTOS!$I$4:$I$63,MATCH($A5,PRODUTOS!$B$4:$B$63,0))="B",INDEX(MODELOS!$I$4:$I$11,MATCH($D5,MODELOS!$A$4:$A$11,0)),INDEX(MODELOS!$E$4:$E$11,MATCH($D5,MODELOS!$A$4:$A$11,0))) -> 970 × 300 | I5: =IF($D5="COMP","SIM",IF(INDEX(PRODUTOS!$J$4:$J$63,MATCH($A5,PRODUTOS!$B$4:$B$63,0))<>"","NÃO (usa o A+ do EAN "&INDEX(PRODUTOS!$J$4:$J$63,MATCH($A5,PRODUTOS!$B$4:$B$63,0))&")",IF(AND(INDEX(PRODUTOS!$I$4:$I$63,MATCH($A5,PRODUTOS!$B$4:$B$63,0))="B",$D5="AP07"),"NÃO (modelo B)","SIM"))) -> SIM | J5: Pendente
A6: 7898968541504 | B6: =INDEX(PRODUTOS!$E$4:$E$63,MATCH($A6,PRODUTOS!$B$4:$B$63,0)) -> New Dots Ração Seca Premium para Cães Adultos - 15 kg | C6: =INDEX(PRODUTOS!$H$4:$H$63,MATCH($A6,PRODUTOS!$B$4:$B$63,0)) -> 15 kg | D6: AP03 | E6: =$A6&"."&$D6&".jpg" -> 7898968541504.AP03.jpg | F6: =IF(INDEX(PRODUTOS!$I$4:$I$63,MATCH($A6,PRODUTOS!$B$4:$B$63,0))="B",INDEX(MODELOS!$F$4:$F$11,MATCH($D6,MODELOS!$A$4:$A$11,0)),INDEX(MODELOS!$B$4:$B$11,MATCH($D6,MODELOS!$A$4:$A$11,0))) -> Módulo 3 · Benefício 1 de 4 | G6: =IF(INDEX(PRODUTOS!$F$4:$F$63,MATCH($A6,PRODUTOS!$B$4:$B$63,0))="Ração",IF(INDEX(PRODUTOS!$I$4:$I$63,MATCH($A6,PRODUTOS!$B$4:$B$63,0))="B",INDEX(MODELOS!$G$4:$G$11,MATCH($D6,MODELOS!$A$4:$A$11,0)),INDEX(MODELOS!$C$4:$C$11,MATCH($D6,MODELOS!$A$4:$A$11,0))),IF(INDEX(PRODUTOS!$I$4:$I$63,MATCH($A6,PRODUTOS!$B$4:$B$63,0))="B",INDEX(MODELOS!$H$4:$H$11,MATCH($D6,MODELOS!$A$4:$A$11,0)),INDEX(MODELOS!$D$4:$D$11,MATCH($D6,MODELOS!$A$4:$A$11,0)))) -> Foto/ilustração do benefício 1 | H6: =IF(INDEX(PRODUTOS!$I$4:$I$63,MATCH($A6,PRODUTOS!$B$4:$B$63,0))="B",INDEX(MODELOS!$I$4:$I$11,MATCH($D6,MODELOS!$A$4:$A$11,0)),INDEX(MODELOS!$E$4:$E$11,MATCH($D6,MODELOS!$A$4:$A$11,0))) -> 220 × 200 | I6: =IF($D6="COMP","SIM",IF(INDEX(PRODUTOS!$J$4:$J$63,MATCH($A6,PRODUTOS!$B$4:$B$63,0))<>"","NÃO (usa o A+ do EAN "&INDEX(PRODUTOS!$J$4:$J$63,MATCH($A6,PRODUTOS!$B$4:$B$63,0))&")",IF(AND(INDEX(PRODUTOS!$I$4:$I$63,MATCH($A6,PRODUTOS!$B$4:$B$63,0))="B",$D6="AP07"),"NÃO (modelo B)","SIM"))) -> SIM | J6: Pendente
A7: 7898968541504 | B7: =INDEX(PRODUTOS!$E$4:$E$63,MATCH($A7,PRODUTOS!$B$4:$B$63,0)) -> New Dots Ração Seca Premium para Cães Adultos - 15 kg | C7: =INDEX(PRODUTOS!$H$4:$H$63,MATCH($A7,PRODUTOS!$B$4:$B$63,0)) -> 15 kg | D7: AP04 | E7: =$A7&"."&$D7&".jpg" -> 7898968541504.AP04.jpg | F7: =IF(INDEX(PRODUTOS!$I$4:$I$63,MATCH($A7,PRODUTOS!$B$4:$B$63,0))="B",INDEX(MODELOS!$F$4:$F$11,MATCH($D7,MODELOS!$A$4:$A$11,0)),INDEX(MODELOS!$B$4:$B$11,MATCH($D7,MODELOS!$A$4:$A$11,0))) -> Módulo 3 · Benefício 2 de 4 | G7: =IF(INDEX(PRODUTOS!$F$4:$F$63,MATCH($A7,PRODUTOS!$B$4:$B$63,0))="Ração",IF(INDEX(PRODUTOS!$I$4:$I$63,MATCH($A7,PRODUTOS!$B$4:$B$63,0))="B",INDEX(MODELOS!$G$4:$G$11,MATCH($D7,MODELOS!$A$4:$A$11,0)),INDEX(MODELOS!$C$4:$C$11,MATCH($D7,MODELOS!$A$4:$A$11,0))),IF(INDEX(PRODUTOS!$I$4:$I$63,MATCH($A7,PRODUTOS!$B$4:$B$63,0))="B",INDEX(MODELOS!$H$4:$H$11,MATCH($D7,MODELOS!$A$4:$A$11,0)),INDEX(MODELOS!$D$4:$D$11,MATCH($D7,MODELOS!$A$4:$A$11,0)))) -> Foto/ilustração do benefício 2 | H7: =IF(INDEX(PRODUTOS!$I$4:$I$63,MATCH($A7,PRODUTOS!$B$4:$B$63,0))="B",INDEX(MODELOS!$I$4:$I$11,MATCH($D7,MODELOS!$A$4:$A$11,0)),INDEX(MODELOS!$E$4:$E$11,MATCH($D7,MODELOS!$A$4:$A$11,0))) -> 220 × 200 | I7: =IF($D7="COMP","SIM",IF(INDEX(PRODUTOS!$J$4:$J$63,MATCH($A7,PRODUTOS!$B$4:$B$63,0))<>"","NÃO (usa o A+ do EAN "&INDEX(PRODUTOS!$J$4:$J$63,MATCH($A7,PRODUTOS!$B$4:$B$63,0))&")",IF(AND(INDEX(PRODUTOS!$I$4:$I$63,MATCH($A7,PRODUTOS!$B$4:$B$63,0))="B",$D7="AP07"),"NÃO (modelo B)","SIM"))) -> SIM | J7: Pendente
A8: 7898968541504 | B8: =INDEX(PRODUTOS!$E$4:$E$63,MATCH($A8,PRODUTOS!$B$4:$B$63,0)) -> New Dots Ração Seca Premium para Cães Adultos - 15 kg | C8: =INDEX(PRODUTOS!$H$4:$H$63,MATCH($A8,PRODUTOS!$B$4:$B$63,0)) -> 15 kg | D8: AP05 | E8: =$A8&"."&$D8&".jpg" -> 7898968541504.AP05.jpg | F8: =IF(INDEX(PRODUTOS!$I$4:$I$63,MATCH($A8,PRODUTOS!$B$4:$B$63,0))="B",INDEX(MODELOS!$F$4:$F$11,MATCH($D8,MODELOS!$A$4:$A$11,0)),INDEX(MODELOS!$B$4:$B$11,MATCH($D8,MODELOS!$A$4:$A$11,0))) -> Módulo 3 · Benefício 3 de 4 | G8: =IF(INDEX(PRODUTOS!$F$4:$F$63,MATCH($A8,PRODUTOS!$B$4:$B$63,0))="Ração",IF(INDEX(PRODUTOS!$I$4:$I$63,MATCH($A8,PRODUTOS!$B$4:$B$63,0))="B",INDEX(MODELOS!$G$4:$G$11,MATCH($D8,MODELOS!$A$4:$A$11,0)),INDEX(MODELOS!$C$4:$C$11,MATCH($D8,MODELOS!$A$4:$A$11,0))),IF(INDEX(PRODUTOS!$I$4:$I$63,MATCH($A8,PRODUTOS!$B$4:$B$63,0))="B",INDEX(MODELOS!$H$4:$H$11,MATCH($D8,MODELOS!$A$4:$A$11,0)),INDEX(MODELOS!$D$4:$D$11,MATCH($D8,MODELOS!$A$4:$A$11,0)))) -> Foto/ilustração do benefício 3 | H8: =IF(INDEX(PRODUTOS!$I$4:$I$63,MATCH($A8,PRODUTOS!$B$4:$B$63,0))="B",INDEX(MODELOS!$I$4:$I$11,MATCH($D8,MODELOS!$A$4:$A$11,0)),INDEX(MODELOS!$E$4:$E$11,MATCH($D8,MODELOS!$A$4:$A$11,0))) -> 220 × 200 | I8: =IF($D8="COMP","SIM",IF(INDEX(PRODUTOS!$J$4:$J$63,MATCH($A8,PRODUTOS!$B$4:$B$63,0))<>"","NÃO (usa o A+ do EAN "&INDEX(PRODUTOS!$J$4:$J$63,MATCH($A8,PRODUTOS!$B$4:$B$63,0))&")",IF(AND(INDEX(PRODUTOS!$I$4:$I$63,MATCH($A8,PRODUTOS!$B$4:$B$63,0))="B",$D8="AP07"),"NÃO (modelo B)","SIM"))) -> SIM | J8: Pendente
A9: 7898968541504 | B9: =INDEX(PRODUTOS!$E$4:$E$63,MATCH($A9,PRODUTOS!$B$4:$B$63,0)) -> New Dots Ração Seca Premium para Cães Adultos - 15 kg | C9: =INDEX(PRODUTOS!$H$4:$H$63,MATCH($A9,PRODUTOS!$B$4:$B$63,0)) -> 15 kg | D9: AP06 | E9: =$A9&"."&$D9&".jpg" -> 7898968541504.AP06.jpg | F9: =IF(INDEX(PRODUTOS!$I$4:$I$63,MATCH($A9,PRODUTOS!$B$4:$B$63,0))="B",INDEX(MODELOS!$F$4:$F$11,MATCH($D9,MODELOS!$A$4:$A$11,0)),INDEX(MODELOS!$B$4:$B$11,MATCH($D9,MODELOS!$A$4:$A$11,0))) -> Módulo 3 · Benefício 4 de 4 | G9: =IF(INDEX(PRODUTOS!$F$4:$F$63,MATCH($A9,PRODUTOS!$B$4:$B$63,0))="Ração",IF(INDEX(PRODUTOS!$I$4:$I$63,MATCH($A9,PRODUTOS!$B$4:$B$63,0))="B",INDEX(MODELOS!$G$4:$G$11,MATCH($D9,MODELOS!$A$4:$A$11,0)),INDEX(MODELOS!$C$4:$C$11,MATCH($D9,MODELOS!$A$4:$A$11,0))),IF(INDEX(PRODUTOS!$I$4:$I$63,MATCH($A9,PRODUTOS!$B$4:$B$63,0))="B",INDEX(MODELOS!$H$4:$H$11,MATCH($D9,MODELOS!$A$4:$A$11,0)),INDEX(MODELOS!$D$4:$D$11,MATCH($D9,MODELOS!$A$4:$A$11,0)))) -> Foto/ilustração do benefício 4 | H9: =IF(INDEX(PRODUTOS!$I$4:$I$63,MATCH($A9,PRODUTOS!$B$4:$B$63,0))="B",INDEX(MODELOS!$I$4:$I$11,MATCH($D9,MODELOS!$A$4:$A$11,0)),INDEX(MODELOS!$E$4:$E$11,MATCH($D9,MODELOS!$A$4:$A$11,0))) -> 220 × 200 | I9: =IF($D9="COMP","SIM",IF(INDEX(PRODUTOS!$J$4:$J$63,MATCH($A9,PRODUTOS!$B$4:$B$63,0))<>"","NÃO (usa o A+ do EAN "&INDEX(PRODUTOS!$J$4:$J$63,MATCH($A9,PRODUTOS!$B$4:$B$63,0))&")",IF(AND(INDEX(PRODUTOS!$I$4:$I$63,MATCH($A9,PRODUTOS!$B$4:$B$63,0))="B",$D9="AP07"),"NÃO (modelo B)","SIM"))) -> SIM | J9: Pendente
A10: 7898968541504 | B10: =INDEX(PRODUTOS!$E$4:$E$63,MATCH($A10,PRODUTOS!$B$4:$B$63,0)) -> New Dots Ração Seca Premium para Cães Adultos - 15 kg | C10: =INDEX(PRODUTOS!$H$4:$H$63,MATCH($A10,PRODUTOS!$B$4:$B$63,0)) -> 15 kg | D10: AP07 | E10: =$A10&"."&$D10&".jpg" -> 7898968541504.AP07.jpg | F10: =IF(INDEX(PRODUTOS!$I$4:$I$63,MATCH($A10,PRODUTOS!$B$4:$B$63,0))="B",INDEX(MODELOS!$F$4:$F$11,MATCH($D10,MODELOS!$A$4:$A$11,0)),INDEX(MODELOS!$B$4:$B$11,MATCH($D10,MODELOS!$A$4:$A$11,0))) -> Módulo 4 · Especificações | G10: =IF(INDEX(PRODUTOS!$F$4:$F$63,MATCH($A10,PRODUTOS!$B$4:$B$63,0))="Ração",IF(INDEX(PRODUTOS!$I$4:$I$63,MATCH($A10,PRODUTOS!$B$4:$B$63,0))="B",INDEX(MODELOS!$G$4:$G$11,MATCH($D10,MODELOS!$A$4:$A$11,0)),INDEX(MODELOS!$C$4:$C$11,MATCH($D10,MODELOS!$A$4:$A$11,0))),IF(INDEX(PRODUTOS!$I$4:$I$63,MATCH($A10,PRODUTOS!$B$4:$B$63,0))="B",INDEX(MODELOS!$H$4:$H$11,MATCH($D10,MODELOS!$A$4:$A$11,0)),INDEX(MODELOS!$D$4:$D$11,MATCH($D10,MODELOS!$A$4:$A$11,0)))) -> Grão ou pacote em destaque | H10: =IF(INDEX(PRODUTOS!$I$4:$I$63,MATCH($A10,PRODUTOS!$B$4:$B$63,0))="B",INDEX(MODELOS!$I$4:$I$11,MATCH($D10,MODELOS!$A$4:$A$11,0)),INDEX(MODELOS!$E$4:$E$11,MATCH($D10,MODELOS!$A$4:$A$11,0))) -> 300 × 300 | I10: =IF($D10="COMP","SIM",IF(INDEX(PRODUTOS!$J$4:$J$63,MATCH($A10,PRODUTOS!$B$4:$B$63,0))<>"","NÃO (usa o A+ do EAN "&INDEX(PRODUTOS!$J$4:$J$63,MATCH($A10,PRODUTOS!$B$4:$B$63,0))&")",IF(AND(INDEX(PRODUTOS!$I$4:$I$63,MATCH($A10,PRODUTOS!$B$4:$B$63,0))="B",$D10="AP07"),"NÃO (modelo B)","SIM"))) -> SIM | J10: Pendente
A11: 7898968541504 | B11: =INDEX(PRODUTOS!$E$4:$E$63,MATCH($A11,PRODUTOS!$B$4:$B$63,0)) -> New Dots Ração Seca Premium para Cães Adultos - 15 kg | C11: =INDEX(PRODUTOS!$H$4:$H$63,MATCH($A11,PRODUTOS!$B$4:$B$63,0)) -> 15 kg | D11: COMP | E11: =$A11&"."&$D11&".jpg" -> 7898968541504.COMP.jpg | F11: =IF(INDEX(PRODUTOS!$I$4:$I$63,MATCH($A11,PRODUTOS!$B$4:$B$63,0))="B",INDEX(MODELOS!$F$4:$F$11,MATCH($D11,MODELOS!$A$4:$A$11,0)),INDEX(MODELOS!$B$4:$B$11,MATCH($D11,MODELOS!$A$4:$A$11,0))) -> Módulo 5 · Tabela comparativa | G11: =IF(INDEX(PRODUTOS!$F$4:$F$63,MATCH($A11,PRODUTOS!$B$4:$B$63,0))="Ração",IF(INDEX(PRODUTOS!$I$4:$I$63,MATCH($A11,PRODUTOS!$B$4:$B$63,0))="B",INDEX(MODELOS!$G$4:$G$11,MATCH($D11,MODELOS!$A$4:$A$11,0)),INDEX(MODELOS!$C$4:$C$11,MATCH($D11,MODELOS!$A$4:$A$11,0))),IF(INDEX(PRODUTOS!$I$4:$I$63,MATCH($A11,PRODUTOS!$B$4:$B$63,0))="B",INDEX(MODELOS!$H$4:$H$11,MATCH($D11,MODELOS!$A$4:$A$11,0)),INDEX(MODELOS!$D$4:$D$11,MATCH($D11,MODELOS!$A$4:$A$11,0)))) -> Pacote na vertical, sem fundo colorido | H11: =IF(INDEX(PRODUTOS!$I$4:$I$63,MATCH($A11,PRODUTOS!$B$4:$B$63,0))="B",INDEX(MODELOS!$I$4:$I$11,MATCH($D11,MODELOS!$A$4:$A$11,0)),INDEX(MODELOS!$E$4:$E$11,MATCH($D11,MODELOS!$A$4:$A$11,0))) -> 150 × 300 | I11: =IF($D11="COMP","SIM",IF(INDEX(PRODUTOS!$J$4:$J$63,MATCH($A11,PRODUTOS!$B$4:$B$63,0))<>"","NÃO (usa o A+ do EAN "&INDEX(PRODUTOS!$J$4:$J$63,MATCH($A11,PRODUTOS!$B$4:$B$63,0))&")",IF(AND(INDEX(PRODUTOS!$I$4:$I$63,MATCH($A11,PRODUTOS!$B$4:$B$63,0))="B",$D11="AP07"),"NÃO (modelo B)","SIM"))) -> SIM | J11: Pendente
A12: 7908591301144 | B12: =INDEX(PRODUTOS!$E$4:$E$63,MATCH($A12,PRODUTOS!$B$4:$B$63,0)) -> New Dots Ração Seca Premium para Cães Adultos - 10,1 kg | C12: =INDEX(PRODUTOS!$H$4:$H$63,MATCH($A12,PRODUTOS!$B$4:$B$63,0)) -> 10,1 kg | D12: AP01 | E12: =$A12&"."&$D12&".jpg" -> 7908591301144.AP01.jpg | F12: =IF(INDEX(PRODUTOS!$I$4:$I$63,MATCH($A12,PRODUTOS!$B$4:$B$63,0))="B",INDEX(MODELOS!$F$4:$F$11,MATCH($D12,MODELOS!$A$4:$A$11,0)),INDEX(MODELOS!$B$4:$B$11,MATCH($D12,MODELOS!$A$4:$A$11,0))) -> Módulo 1 · Banner | G12: =IF(INDEX(PRODUTOS!$F$4:$F$63,MATCH($A12,PRODUTOS!$B$4:$B$63,0))="Ração",IF(INDEX(PRODUTOS!$I$4:$I$63,MATCH($A12,PRODUTOS!$B$4:$B$63,0))="B",INDEX(MODELOS!$G$4:$G$11,MATCH($D12,MODELOS!$A$4:$A$11,0)),INDEX(MODELOS!$C$4:$C$11,MATCH($D12,MODELOS!$A$4:$A$11,0))),IF(INDEX(PRODUTOS!$I$4:$I$63,MATCH($A12,PRODUTOS!$B$4:$B$63,0))="B",INDEX(MODELOS!$H$4:$H$11,MATCH($D12,MODELOS!$A$4:$A$11,0)),INDEX(MODELOS!$D$4:$D$11,MATCH($D12,MODELOS!$A$4:$A$11,0)))) -> Embalagem + pet + ingredientes, com o nome da linha | H12: =IF(INDEX(PRODUTOS!$I$4:$I$63,MATCH($A12,PRODUTOS!$B$4:$B$63,0))="B",INDEX(MODELOS!$I$4:$I$11,MATCH($D12,MODELOS!$A$4:$A$11,0)),INDEX(MODELOS!$E$4:$E$11,MATCH($D12,MODELOS!$A$4:$A$11,0))) -> 970 × 600 | I12: =IF($D12="COMP","SIM",IF(INDEX(PRODUTOS!$J$4:$J$63,MATCH($A12,PRODUTOS!$B$4:$B$63,0))<>"","NÃO (usa o A+ do EAN "&INDEX(PRODUTOS!$J$4:$J$63,MATCH($A12,PRODUTOS!$B$4:$B$63,0))&")",IF(AND(INDEX(PRODUTOS!$I$4:$I$63,MATCH($A12,PRODUTOS!$B$4:$B$63,0))="B",$D12="AP07"),"NÃO (modelo B)","SIM"))) -> NÃO (usa o A+ do EAN 7898968541504) | J12: Pendente
A13: 7908591301144 | B13: =INDEX(PRODUTOS!$E$4:$E$63,MATCH($A13,PRODUTOS!$B$4:$B$63,0)) -> New Dots Ração Seca Premium para Cães Adultos - 10,1 kg | C13: =INDEX(PRODUTOS!$H$4:$H$63,MATCH($A13,PRODUTOS!$B$4:$B$63,0)) -> 10,1 kg | D13: AP02 | E13: =$A13&"."&$D13&".jpg" -> 7908591301144.AP02.jpg | F13: =IF(INDEX(PRODUTOS!$I$4:$I$63,MATCH($A13,PRODUTOS!$B$4:$B$63,0))="B",INDEX(MODELOS!$F$4:$F$11,MATCH($D13,MODELOS!$A$4:$A$11,0)),INDEX(MODELOS!$B$4:$B$11,MATCH($D13,MODELOS!$A$4:$A$11,0))) -> Módulo 2 · Texto sobreposto | G13: =IF(INDEX(PRODUTOS!$F$4:$F$63,MATCH($A13,PRODUTOS!$B$4:$B$63,0))="Ração",IF(INDEX(PRODUTOS!$I$4:$I$63,MATCH($A13,PRODUTOS!$B$4:$B$63,0))="B",INDEX(MODELOS!$G$4:$G$11,MATCH($D13,MODELOS!$A$4:$A$11,0)),INDEX(MODELOS!$C$4:$C$11,MATCH($D13,MODELOS!$A$4:$A$11,0))),IF(INDEX(PRODUTOS!$I$4:$I$63,MATCH($A13,PRODUTOS!$B$4:$B$63,0))="B",INDEX(MODELOS!$H$4:$H$11,MATCH($D13,MODELOS!$A$4:$A$11,0)),INDEX(MODELOS!$D$4:$D$11,MATCH($D13,MODELOS!$A$4:$A$11,0)))) -> Principal diferencial; deixar o lado direito limpo | H13: =IF(INDEX(PRODUTOS!$I$4:$I$63,MATCH($A13,PRODUTOS!$B$4:$B$63,0))="B",INDEX(MODELOS!$I$4:$I$11,MATCH($D13,MODELOS!$A$4:$A$11,0)),INDEX(MODELOS!$E$4:$E$11,MATCH($D13,MODELOS!$A$4:$A$11,0))) -> 970 × 300 | I13: =IF($D13="COMP","SIM",IF(INDEX(PRODUTOS!$J$4:$J$63,MATCH($A13,PRODUTOS!$B$4:$B$63,0))<>"","NÃO (usa o A+ do EAN "&INDEX(PRODUTOS!$J$4:$J$63,MATCH($A13,PRODUTOS!$B$4:$B$63,0))&")",IF(AND(INDEX(PRODUTOS!$I$4:$I$63,MATCH($A13,PRODUTOS!$B$4:$B$63,0))="B",$D13="AP07"),"NÃO (modelo B)","SIM"))) -> NÃO (usa o A+ do EAN 7898968541504) | J13: Pendente
A14: 7908591301144 | B14: =INDEX(PRODUTOS!$E$4:$E$63,MATCH($A14,PRODUTOS!$B$4:$B$63,0)) -> New Dots Ração Seca Premium para Cães Adultos - 10,1 kg | C14: =INDEX(PRODUTOS!$H$4:$H$63,MATCH($A14,PRODUTOS!$B$4:$B$63,0)) -> 10,1 kg | D14: AP03 | E14: =$A14&"."&$D14&".jpg" -> 7908591301144.AP03.jpg | F14: =IF(INDEX(PRODUTOS!$I$4:$I$63,MATCH($A14,PRODUTOS!$B$4:$B$63,0))="B",INDEX(MODELOS!$F$4:$F$11,MATCH($D14,MODELOS!$A$4:$A$11,0)),INDEX(MODELOS!$B$4:$B$11,MATCH($D14,MODELOS!$A$4:$A$11,0))) -> Módulo 3 · Benefício 1 de 4 | G14: =IF(INDEX(PRODUTOS!$F$4:$F$63,MATCH($A14,PRODUTOS!$B$4:$B$63,0))="Ração",IF(INDEX(PRODUTOS!$I$4:$I$63,MATCH($A14,PRODUTOS!$B$4:$B$63,0))="B",INDEX(MODELOS!$G$4:$G$11,MATCH($D14,MODELOS!$A$4:$A$11,0)),INDEX(MODELOS!$C$4:$C$11,MATCH($D14,MODELOS!$A$4:$A$11,0))),IF(INDEX(PRODUTOS!$I$4:$I$63,MATCH($A14,PRODUTOS!$B$4:$B$63,0))="B",INDEX(MODELOS!$H$4:$H$11,MATCH($D14,MODELOS!$A$4:$A$11,0)),INDEX(MODELOS!$D$4:$D$11,MATCH($D14,MODELOS!$A$4:$A$11,0)))) -> Foto/ilustração do benefício 1 | H14: =IF(INDEX(PRODUTOS!$I$4:$I$63,MATCH($A14,PRODUTOS!$B$4:$B$63,0))="B",INDEX(MODELOS!$I$4:$I$11,MATCH($D14,MODELOS!$A$4:$A$11,0)),INDEX(MODELOS!$E$4:$E$11,MATCH($D14,MODELOS!$A$4:$A$11,0))) -> 220 × 200 | I14: =IF($D14="COMP","SIM",IF(INDEX(PRODUTOS!$J$4:$J$63,MATCH($A14,PRODUTOS!$B$4:$B$63,0))<>"","NÃO (usa o A+ do EAN "&INDEX(PRODUTOS!$J$4:$J$63,MATCH($A14,PRODUTOS!$B$4:$B$63,0))&")",IF(AND(INDEX(PRODUTOS!$I$4:$I$63,MATCH($A14,PRODUTOS!$B$4:$B$63,0))="B",$D14="AP07"),"NÃO (modelo B)","SIM"))) -> NÃO (usa o A+ do EAN 7898968541504) | J14: Pendente
A15: 7908591301144 | B15: =INDEX(PRODUTOS!$E$4:$E$63,MATCH($A15,PRODUTOS!$B$4:$B$63,0)) -> New Dots Ração Seca Premium para Cães Adultos - 10,1 kg | C15: =INDEX(PRODUTOS!$H$4:$H$63,MATCH($A15,PRODUTOS!$B$4:$B$63,0)) -> 10,1 kg | D15: AP04 | E15: =$A15&"."&$D15&".jpg" -> 7908591301144.AP04.jpg | F15: =IF(INDEX(PRODUTOS!$I$4:$I$63,MATCH($A15,PRODUTOS!$B$4:$B$63,0))="B",INDEX(MODELOS!$F$4:$F$11,MATCH($D15,MODELOS!$A$4:$A$11,0)),INDEX(MODELOS!$B$4:$B$11,MATCH($D15,MODELOS!$A$4:$A$11,0))) -> Módulo 3 · Benefício 2 de 4 | G15: =IF(INDEX(PRODUTOS!$F$4:$F$63,MATCH($A15,PRODUTOS!$B$4:$B$63,0))="Ração",IF(INDEX(PRODUTOS!$I$4:$I$63,MATCH($A15,PRODUTOS!$B$4:$B$63,0))="B",INDEX(MODELOS!$G$4:$G$11,MATCH($D15,MODELOS!$A$4:$A$11,0)),INDEX(MODELOS!$C$4:$C$11,MATCH($D15,MODELOS!$A$4:$A$11,0))),IF(INDEX(PRODUTOS!$I$4:$I$63,MATCH($A15,PRODUTOS!$B$4:$B$63,0))="B",INDEX(MODELOS!$H$4:$H$11,MATCH($D15,MODELOS!$A$4:$A$11,0)),INDEX(MODELOS!$D$4:$D$11,MATCH($D15,MODELOS!$A$4:$A$11,0)))) -> Foto/ilustração do benefício 2 | H15: =IF(INDEX(PRODUTOS!$I$4:$I$63,MATCH($A15,PRODUTOS!$B$4:$B$63,0))="B",INDEX(MODELOS!$I$4:$I$11,MATCH($D15,MODELOS!$A$4:$A$11,0)),INDEX(MODELOS!$E$4:$E$11,MATCH($D15,MODELOS!$A$4:$A$11,0))) -> 220 × 200 | I15: =IF($D15="COMP","SIM",IF(INDEX(PRODUTOS!$J$4:$J$63,MATCH($A15,PRODUTOS!$B$4:$B$63,0))<>"","NÃO (usa o A+ do EAN "&INDEX(PRODUTOS!$J$4:$J$63,MATCH($A15,PRODUTOS!$B$4:$B$63,0))&")",IF(AND(INDEX(PRODUTOS!$I$4:$I$63,MATCH($A15,PRODUTOS!$B$4:$B$63,0))="B",$D15="AP07"),"NÃO (modelo B)","SIM"))) -> NÃO (usa o A+ do EAN 7898968541504) | J15: Pendente
... A483: 7898968541979 | B483: =INDEX(PRODUTOS!$E$4:$E$63,MATCH($A483,PRODUTOS!$B$4:$B$63,0)) -> Tapete Higiênico Natural Dots Super Premium 80 x 60 cm com 7 Unidades | C483: =INDEX(PRODUTOS!$H$4:$H$63,MATCH($A483,PRODUTOS!$B$4:$B$63,0)) -> 7 un. | D483: COMP | E483: =$A483&"."&$D483&".jpg" -> 7898968541979.COMP.jpg | F483: =IF(INDEX(PRODUTOS!$I$4:$I$63,MATCH($A483,PRODUTOS!$B$4:$B$63,0))="B",INDEX(MODELOS!$F$4:$F$11,MATCH($D483,MODELOS!$A$4:$A$11,0)),INDEX(MODELOS!$B$4:$B$11,MATCH($D483,MODELOS!$A$4:$A$11,0))) -> Módulo 5 · Tabela comparativa | G483: =IF(INDEX(PRODUTOS!$F$4:$F$63,MATCH($A483,PRODUTOS!$B$4:$B$63,0))="Ração",IF(INDEX(PRODUTOS!$I$4:$I$63,MATCH($A483,PRODUTOS!$B$4:$B$63,0))="B",INDEX(MODELOS!$G$4:$G$11,MATCH($D483,MODELOS!$A$4:$A$11,0)),INDEX(MODELOS!$C$4:$C$11,MATCH($D483,MODELOS!$A$4:$A$11,0))),IF(INDEX(PRODUTOS!$I$4:$I$63,MATCH($A483,PRODUTOS!$B$4:$B$63,0))="B",INDEX(MODELOS!$H$4:$H$11,MATCH($D483,MODELOS!$A$4:$A$11,0)),INDEX(MODELOS!$D$4:$D$11,MATCH($D483,MODELOS!$A$4:$A$11,0)))) -> Produto na vertical, sem fundo colorido | H483: =IF(INDEX(PRODUTOS!$I$4:$I$63,MATCH($A483,PRODUTOS!$B$4:$B$63,0))="B",INDEX(MODELOS!$I$4:$I$11,MATCH($D483,MODELOS!$A$4:$A$11,0)),INDEX(MODELOS!$E$4:$E$11,MATCH($D483,MODELOS!$A$4:$A$11,0))) -> 150 × 300 | I483: =IF($D483="COMP","SIM",IF(INDEX(PRODUTOS!$J$4:$J$63,MATCH($A483,PRODUTOS!$B$4:$B$63,0))<>"","NÃO (usa o A+ do EAN "&INDEX(PRODUTOS!$J$4:$J$63,MATCH($A483,PRODUTOS!$B$4:$B$63,0))&")",IF(AND(INDEX(PRODUTOS!$I$4:$I$63,MATCH($A483,PRODUTOS!$B$4:$B$63,0))="B",$D483="AP07"),"NÃO (modelo B)","SIM"))) -> SIM | J483: Pendente

Sheet MODELOS
A1: Modelos de A+ · o que mostrar em cada imagem
A2: Consulta. Detalhes e desenhos dos módulos no Guia do Conteúdo A+.
A3: Código | B3: Modelo A · Onde entra | C3: Modelo A · O que mostrar (Ração) | D3: Modelo A · O que mostrar (Petiscos e higiene) | E3: Modelo A · Tamanho (px) | F3: Modelo B · Onde entra | G3: Modelo B · O que mostrar (Ração) | H3: Modelo B · O que mostrar (Petiscos e higiene) | I3: Modelo B · Tamanho (px)
A4: AP01 | B4: Módulo 1 · Banner | C4: Embalagem + pet + ingredientes, com o nome da linha | D4: Produto + pet, com o nome da linha | E4: 970 × 600 | F4: Módulo 1 · Banner | G4: Cena principal da linha | H4: Cena principal da linha | I4: 970 × 600
A5: AP02 | B5: Módulo 2 · Texto sobreposto | C5: Principal diferencial; deixar o lado direito limpo | D5: Principal diferencial; deixar o lado direito limpo | E5: 970 × 300 | F5: Módulo 2 · Imagem com destaques | G5: Pacote ou grão em destaque | H5: Produto em destaque | I5: 300 × 300
A6: AP03 | B6: Módulo 3 · Benefício 1 de 4 | C6: Foto/ilustração do benefício 1 | D6: Foto/ilustração do benefício 1 | E6: 220 × 200 | F6: Módulo 3 · Imagem 1 de 3 | G6: Ingrediente 1 (ex.: frango) | H6: Benefício 1 | I6: 300 × 300
A7: AP04 | B7: Módulo 3 · Benefício 2 de 4 | C7: Foto/ilustração do benefício 2 | D7: Foto/ilustração do benefício 2 | E7: 220 × 200 | F7: Módulo 3 · Imagem 2 de 3 | G7: Ingrediente 2 (ex.: arroz) | H7: Benefício 2 | I7: 300 × 300
A8: AP05 | B8: Módulo 3 · Benefício 3 de 4 | C8: Foto/ilustração do benefício 3 | D8: Foto/ilustração do benefício 3 | E8: 220 × 200 | F8: Módulo 3 · Imagem 3 de 3 | G8: Ingrediente 3 (ex.: linhaça) | H8: Benefício 3 | I8: 300 × 300
A9: AP06 | B9: Módulo 3 · Benefício 4 de 4 | C9: Foto/ilustração do benefício 4 | D9: Foto/ilustração do benefício 4 | E9: 220 × 200 | F9: Módulo 4 · Texto sobreposto | G9: Momento de uso; deixar o lado direito limpo | H9: Momento de uso; deixar o lado direito limpo | I9: 970 × 300
A10: AP07 | B10: Módulo 4 · Especificações | C10: Grão ou pacote em destaque | D10: Produto em destaque | E10: 300 × 300 | F10: Não usado no modelo B | G10: - | H10: - | I10: -
A11: COMP | B11: Módulo 5 · Tabela comparativa | C11: Pacote na vertical, sem fundo colorido | D11: Produto na vertical, sem fundo colorido | E11: 150 × 300 | F11: Módulo 5 · Tabela comparativa | G11: Pacote na vertical, sem fundo colorido | H11: Produto na vertical, sem fundo colorido | I11: 150 × 300
